Workbook

Sheet ACCUEIL
B2: GESTION DE LA FORMATION – EMSP
B3: Outil de pilotage pédagogique et administratif
B5: 🔵 Texte NOIR = champs définis dans le cahier des charges 🔴 Texte ROUGE = ajouts complémentaires pris à notre initiative
B7: Onglet | C7: Description | D7: Fréquence de mise à jour
B8: 📋 PARAM_SALLES | C8: Référentiel des salles pédagogiques | D8: À chaque changement de salle
B9: 📚 PARAM_FORMATIONS | C9: Référentiel des formations (catalogue) | D9: À chaque nouvelle formation
B10: 👩‍🏫 FORMATEURS_RH | C10: Profils et disponibilités des formateurs | D10: À chaque arrivée / départ / MAJ
B11: 📅 SESSIONS | C11: Sessions planifiées et réalisées | D11: À chaque session planifiée
B12: 🔗 INTERVENTIONS | C12: Affectation formateurs ↔ sessions | D12: À chaque affectation
B13: 🏫 RESERVATIONS | C13: Planning d'occupation des salles | D13: Avant chaque utilisation de salle
B14: 💶 DEPENSES | C14: Suivi financier des dépenses par session | D14: À chaque dépense engagée
B15: 📊 BILANS | C15: Tableau de bord et indicateurs automatiques | D15: Automatique (formules dynamiques)
B16: 📋 LISTES | C16: Listes de référence (validation données) | D16: Au démarrage + si besoin
B19: Légende des codes couleur (mises en forme conditionnelles)
B20: 🔴 Ligne rouge | C20: Équipement / session critique à traiter en urgence
B21: 🟠 Ligne orange | C21: Maintenance ou action en retard
B22: 🟡 Ligne jaune | C22: Alerte ou point d'attention
B23: 🟢 Ligne verte | C23: Réalisé / conforme

Sheet LISTES
A1: Type_Formation | B1: Statut_Session | C1: Type_Public | D1: Statut_Salle | E1: Type_Salle | F1: Statut_Formateur | G1: Niveau_Qualification | H1: Rôle_Intervention | I1: Nature_Depense | J1: Mode_Paiement | K1: Source_Financement | L1: Taux_Disponibilite | M1: Filiere (ajout) | N1: Statut_Reservation (ajout) | O1: Type_Activite (ajout)
A2: Initiale | B2: Planifiée | C2: Étudiants EMSP | D2: En service | E2: Amphi | F2: Interne EMSP | G2: Licence | H2: Responsable | I2: Intervenants | J2: Virement | K2: ODS | L2: Plein temps | M2: Infirmier | N2: Prévu | O2: Cours initial
A3: Continue | B3: En cours | C3: Agents hospitaliers | D3: Hors service | E3: TP | F3: Intervenant externe | G3: Master | H3: Co-formateur | I3: Supports pédagogiques | J3: Chèque | K3: Budget EMSP | L3: Temps partiel | M3: Aide-soignant | N3: Confirmé | O3: TP
A4: Recyclage | B4: Terminée | C4: Formateurs EMSP | D4: En rénovation | E4: Simulation | F4: Expert projet | G4: Doctorat | H4: Intervenant externe | I4: Matériel TP | J4: Espèces | K4: Projet | L4: Occasionnel | M4: Médecin | N4: Réalisé | O4: Simulation
B5: Annulée | C5: Mixte | D5: Réservée | E5: Cours | F5: Enseignant UDC | G5: Spécialiste | H5: Tuteur stage | I5: Hébergement | J5: Prélèvement | K5: Partenariat | L5: Vacataire | M5: Pharmacien | N5: Annulé | O5: Formation continue
B6: Reportée | C6: Externe | E6: Réunion | F6: Vacataire | G6: DES | H6: Observateur | I6: Transport | J6: Bon de commande | K6: Autofinancement | M6: Transversal | N6: Reporté | O6: Réunion
E7: Laboratoire | G7: DESC | I7: Collations | M7: Formateurs | O7: Examen
I8: Location matériel
I9: Fournitures administratives
I10: Autre

Sheet PARAM_FORMATIONS
A1: Code_Formation | B1: Intitulé | C1: Type_Formation | D1: Filière | E1: Durée (h) | F1: Responsable_Pédagogique | G1: Coût_Prévisionnel (FCFA) | H1: Financement_Principal | I1: Nb_Max_Participants | J1: Objectifs_Généraux | K1: Pré-requis
A2: FI-INF-01 | B2: Formation Initiale Infirmier – 1ère année | C2: Initiale | D2: Infirmier | E2: 600 | F2: Dr. Dupont | G2: 0 | H2: ODS | I2: 80 | K2: BAC ou équivalent
A3: FI-INF-02 | B3: Formation Initiale Infirmier – 2ème année | C3: Initiale | D3: Infirmier | E3: 680 | F3: Dr. Dupont | G3: 0 | H3: ODS | I3: 80 | K3: Valider FI-INF-01
A4: FI-INF-03 | B4: Formation Initiale Infirmier – 3ème année | C4: Initiale | D4: Infirmier | E4: 720 | F4: Dr. Dupont | G4: 0 | H4: ODS | I4: 80 | K4: Valider FI-INF-02
A5: FI-AS-01 | B5: Formation Initiale Aide-Soignant | C5: Initiale | D5: Aide-soignant | E5: 350 | F5: Mme Martin | G5: 0 | H5: ODS | I5: 40 | K5: Aucun
A6: FC-HYG-01 | B6: Formation Continue Hygiène Hospitalière | C6: Continue | D6: Transversal | E6: 16 | F6: Dr. Bernard | G6: 250000 | H6: Budget EMSP | I6: 30 | K6: Aucun
A7: FC-GES-01 | B7: Formation Continue Gestes d'urgence | C7: Continue | D7: Transversal | E7: 8 | F7: Dr. Leroy | G7: 120000 | H7: Budget EMSP | I7: 25 | K7: Aucun
A8: FC-SIM-01 | B8: Pédagogie par la Simulation | C8: Continue | D8: Formateurs | E8: 24 | F8: Mme Leclerc | G8: 180000 | H8: Projet | I8: 16 | K8: Expérience enseignement
A9: FC-DID-01 | B9: Didactique et Pédagogie Médicale | C9: Continue | D9: Formateurs | E9: 32 | F9: Pr. Morin | G9: 220000 | H9: Projet | I9: 20 | K9: Fonction pédagogique

Sheet PARAM_SALLES
A1: Code_Salle | B1: Nom_Salle | C1: Type_Salle | D1: Capacité | E1: Bâtiment | F1: Étage | G1: Équipements | H1: Statut | I1: Resp. Salle | J1: Observations
A2: SAL-AMP-01 | B2: Amphi A | C2: Amphi | D2: 120 | E2: Bât. A | F2: RDC | G2: Vidéo, Sono, Microphone | H2: En service
A3: SAL-TP-01 | B3: Salle TP 1 | C3: TP | D3: 24 | E3: Bât. B | F3: R+1 | G3: Mannequins, Matériel soins | H3: En service | J3: Groupe max 12 par rotation
A4: SAL-TP-02 | B4: Salle TP 2 | C4: TP | D4: 24 | E4: Bât. B | F4: R+1 | G4: Mannequins, Matériel soins | H4: En service
A5: SAL-COURS-01 | B5: Salle de Cours 1 | C5: Cours | D5: 40 | E5: Bât. A | F5: R+1 | G5: Vidéo, Tableau blanc | H5: En service
A6: SAL-COURS-02 | B6: Salle de Cours 2 | C6: Cours | D6: 40 | E6: Bât. A | F6: R+2 | G6: Vidéo, Tableau blanc | H6: En service
A7: SAL-SIM-01 | B7: Centre Simulation | C7: Simulation | D7: 16 | E7: Bât. C | F7: RDC | G7: Sim. haute-fidélité, Enregistrement | H7: En service | J7: Accès réservé formateurs certifiés
A8: SAL-REU-01 | B8: Salle de Réunion | C8: Réunion | D8: 20 | E8: Admin | F8: R+1 | G8: Vidéo, Écran tactile | H8: En service

Sheet FORMATEURS_RH
A1: Code_Formateur | B1: Nom | C1: Prénom | D1: Statut | E1: Discipline_Principale | F1: Niveau_Qualification | G1: Type_Intervention | H1: Exp. Ens. (ans) | I1: Exp. Clinique (ans) | J1: Taux_Disponibilité | K1: Rattachement_Institutionnel | L1: Formations_Suivies_Projet | M1: Date_Dernière_MAJ | N1: Email | O1: Téléphone | P1: Heures_Max_S1
A2: F001 | B2: CHABRUT | C2: Luc | D2: Interne EMSP | E2: Soins infirmiers | F2: Master | G2: Cours magistral, TP | H2: 8 | I2: 12 | J2: Plein temps | K2: EMSP | L2: Pédagogie par la simulation – 2026 | M2: 2026-01-15 | P2: 300
A3: F002 | B3: MARTIN | C3: Sophie | D3: Interne EMSP | E3: Pédagogie | F3: Master | G3: Cours magistral, Simulation | H3: 6 | I3: 5 | J3: Plein temps | K3: EMSP | L3: Didactique – 2025, Simulation – 2026 | M3: 2026-01-15 | P3: 300
A4: F003 | B4: BERNARD | C4: Jean | D4: Interne EMSP | E4: Hygiène hospitalière | F4: Doctorat | G4: Cours magistral, Formation continue | H4: 10 | I4: 15 | J4: Plein temps | K4: EMSP | M4: 2026-01-10 | P4: 300
A5: F004 | B5: LEROY | C5: Claire | D5: Interne EMSP | E5: Médecine d'urgence | F5: Doctorat | G5: TP, Simulation | H5: 4 | I5: 20 | J5: Temps partiel | K5: Hôpital Central | L5: Simulation – 2026 | M5: 2026-02-01 | P5: 150
A6: F005 | B6: MORIN | C6: Paul | D6: Expert projet | E6: Pédagogie médicale | F6: Doctorat | G6: Cours magistral, Formation continue | H6: 20 | I6: 5 | J6: Vacataire | K6: Université | M6: 2025-12-01 | P6: 80
A7: F006 | B7: LECLERC | C7: Amélie | D7: Intervenant externe | E7: Simulation médicale | F7: Master | G7: Simulation, Formation continue | H7: 7 | I7: 8 | J7: Vacataire | K7: Privé | L7: Simulation – 2025 | M7: 2025-11-15 | P7: 60
A8: F007 | B8: DUPONT | C8: Marc | D8: Enseignant UDC | E8: Biomédical | F8: Doctorat | G8: Cours magistral | H8: 15 | I8: 2 | J8: Temps partiel | K8: Université | M8: 2025-10-01 | P8: 80
A9: F008 | B9: AHMED | C9: Fatima | D9: Intervenant externe | E9: Pharmacologie | F9: Master | G9: Cours magistral | H9: 3 | I9: 10 | J9: Occasionnel | K9: Hôpital Nord | M9: 2026-01-20 | P9: 40

Sheet SESSIONS
A1: Code_Session | B1: Code_Formation | C1: Intitulé_Session | D1: Date_Début | E1: Date_Fin | F1: Responsable_Session | G1: Nb_Participants_Prévus | H1: Nb_Participants_Réels | I1: Type_Public | J1: Statut_Session | K1: Taux_Réalisation | L1: Lieu_Principal | M1: Observations
A2: FI-INF-01-2026-S1 | B2: FI-INF-01 | C2: Formation Infirmier 1A – S1 2026 | D2: 46027 | E2: 46203 | F2: Dr. Dupont | G2: 80 | H2: 78 | I2: Étudiants EMSP | J2: En cours | K2: =IF(G2=0,"–",H2/G2) | L2: SAL-AMP-01
A3: FI-INF-02-2026-S1 | B3: FI-INF-02 | C3: Formation Infirmier 2A – S1 2026 | D3: 46027 | E3: 46203 | F3: Dr. Dupont | G3: 75 | H3: 74 | I3: Étudiants EMSP | J3: En cours | K3: =IF(G3=0,"–",H3/G3) | L3: SAL-AMP-01
A4: FI-AS-01-2026-S1 | B4: FI-AS-01 | C4: Formation Aide-Soignant – S1 2026 | D4: 46034 | E4: 46188 | F4: Mme Martin | G4: 40 | H4: 38 | I4: Étudiants EMSP | J4: En cours | K4: =IF(G4=0,"–",H4/G4) | L4: SAL-TP-01
A5: FC-HYG-01-2026-01 | B5: FC-HYG-01 | C5: Hygiène Hospitalière – Mars 2026 | D5: 46090 | E5: 46091 | F5: Dr. Bernard | G5: 30 | H5: 28 | I5: Agents hospitaliers | J5: Terminée | K5: =IF(G5=0,"–",H5/G5) | L5: SAL-COURS-01
A6: FC-GES-01-2026-01 | B6: FC-GES-01 | C6: Gestes d'urgence – Avril 2026 | D6: 46118 | E6: 46118 | F6: Dr. Leroy | G6: 25 | H6: 25 | I6: Agents hospitaliers | J6: Terminée | K6: =IF(G6=0,"–",H6/G6) | L6: SAL-SIM-01
A7: FC-SIM-01-2026-01 | B7: FC-SIM-01 | C7: Simulation – Formation Formateurs | D7: 46069 | E7: 46071 | F7: Mme Leclerc | G7: 16 | H7: 15 | I7: Mixte | J7: Terminée | K7: =IF(G7=0,"–",H7/G7) | L7: SAL-SIM-01
A8: FC-DID-01-2026-01 | B8: FC-DID-01 | C8: Didactique Médicale – Formateurs | D8: 46153 | E8: 46156 | F8: Pr. Morin | G8: 20 | H8: 0 | I8: Formateurs EMSP | J8: Planifiée | K8: =IF(G8=0,"–",H8/G8) | L8: SAL-COURS-02
A9: FI-INF-01-2026-S2 | B9: FI-INF-01 | C9: Formation Infirmier 1A – S2 2026 | D9: 46266 | E9: 46446 | F9: Dr. Dupont | G9: 80 | H9: 0 | I9: Étudiants EMSP | J9: Planifiée | K9: =IF(G9=0,"–",H9/G9) | L9: SAL-AMP-01

Sheet INTERVENTIONS
A1: Code_Intervention | B1: Code_Session | C1: Code_Formateur | D1: Rôle | E1: Nb_Heures | F1: Date_Début_Session | G1: Intitulé_Formateur | H1: Intitulé_Session | I1: Observations
A2: INT_001 | B2: FI-INF-01-2026-S1 | C2: F001 | D2: Responsable | E2: 280 | F2: 46027 | G2: CHABRUT Luc | H2: Formation Infirmier 1A – S1 2026
A3: INT_002 | B3: FI-INF-01-2026-S1 | C3: F002 | D3: Co-formateur | E3: 120 | F3: 46027 | G3: MARTIN Sophie | H3: Formation Infirmier 1A – S1 2026
A4: INT_003 | B4: FI-INF-02-2026-S1 | C4: F001 | D4: Responsable | E4: 200 | F4: 46027 | G4: CHABRUT Luc | H4: Formation Infirmier 2A – S1 2026
A5: INT_004 | B5: FI-INF-02-2026-S1 | C5: F004 | D5: Co-formateur | E5: 80 | F5: 46027 | G5: LEROY Claire | H5: Formation Infirmier 2A – S1 2026
A6: INT_005 | B6: FI-AS-01-2026-S1 | C6: F002 | D6: Responsable | E6: 180 | F6: 46034 | G6: MARTIN Sophie | H6: Formation Aide-Soignant – S1 2026
A7: INT_006 | B7: FC-HYG-01-2026-01 | C7: F003 | D7: Responsable | E7: 16 | F7: 46090 | G7: BERNARD Jean | H7: Hygiène Hospitalière – Mars 2026
A8: INT_007 | B8: FC-GES-01-2026-01 | C8: F004 | D8: Responsable | E8: 8 | F8: 46118 | G8: LEROY Claire | H8: Gestes d'urgence – Avril 2026
A9: INT_008 | B9: FC-SIM-01-2026-01 | C9: F006 | D9: Responsable | E9: 24 | F9: 46069 | G9: LECLERC Amélie | H9: Simulation – Formation Formateurs
A10: INT_009 | B10: FC-SIM-01-2026-01 | C10: F002 | D10: Co-formateur | E10: 12 | F10: 46069 | G10: MARTIN Sophie | H10: Simulation – Formation Formateurs
A11: INT_010 | B11: FC-DID-01-2026-01 | C11: F005 | D11: Responsable | E11: 32 | F11: 46153 | G11: MORIN Paul | H11: Didactique Médicale – Formateurs
A12: INT_011 | B12: FI-INF-01-2026-S1 | C12: F007 | D12: Intervenant externe | E12: 40 | F12: 46027 | G12: DUPONT Marc | H12: Formation Infirmier 1A – S1 2026
A13: INT_012 | B13: FC-HYG-01-2026-01 | C13: F008 | D13: Co-formateur | E13: 8 | F13: 46090 | G13: AHMED Fatima | H13: Hygiène Hospitalière – Mars 2026

Sheet RESERVATIONS
A1: Date | B1: Heure_Début | C1: Heure_Fin | D1: Code_Salle | E1: Type_Activité | F1: Intitulé_Activité | G1: Responsable | H1: Lien_Session | I1: Statut | J1: Commentaire | K1: Durée (h) | L1: Capacité_Salle
A2: 46027 | B2: 08:00 | C2: 10:00 | D2: SAL-AMP-01 | E2: Cours initial | F2: Anatomie S1 | G2: Dr. Dupont | H2: FI-INF-01-2026-S1 | I2: Réalisé | K2: =IF(AND(C2<>"",B2<>""),TIMEVALUE(C2)-TIMEVALUE(B2),"–") | L2: 120
A3: 46027 | B3: 10:00 | C3: 12:00 | D3: SAL-TP-01 | E3: TP | F3: TP Soins de base Gr A | G3: Mme Martin | H3: FI-INF-01-2026-S1 | I3: Réalisé | K3: =IF(AND(C3<>"",B3<>""),TIMEVALUE(C3)-TIMEVALUE(B3),"–") | L3: 24
A4: 46027 | B4: 13:00 | C4: 15:00 | D4: SAL-TP-02 | E4: TP | F4: TP Soins de base Gr B | G4: Mme Martin | H4: FI-INF-01-2026-S1 | I4: Réalisé | K4: =IF(AND(C4<>"",B4<>""),TIMEVALUE(C4)-TIMEVALUE(B4),"–") | L4: 24
A5: 46090 | B5: 08:30 | C5: 17:30 | D5: SAL-COURS-01 | E5: Formation continue | F5: Hygiène Hospitalière J1 | G5: Dr. Bernard | H5: FC-HYG-01-2026-01 | I5: Réalisé | K5: =IF(AND(C5<>"",B5<>""),TIMEVALUE(C5)-TIMEVALUE(B5),"–") | L5: 40
A6: 46091 | B6: 08:30 | C6: 17:30 | D6: SAL-COURS-01 | E6: Formation continue | F6: Hygiène Hospitalière J2 | G6: Dr. Bernard | H6: FC-HYG-01-2026-01 | I6: Réalisé | K6: =IF(AND(C6<>"",B6<>""),TIMEVALUE(C6)-TIMEVALUE(B6),"–") | L6: 40
A7: 46118 | B7: 08:00 | C7: 16:00 | D7: SAL-SIM-01 | E7: Formation continue | F7: Gestes d'urgence | G7: Dr. Leroy | H7: FC-GES-01-2026-01 | I7: Réalisé | K7: =IF(AND(C7<>"",B7<>""),TIMEVALUE(C7)-TIMEVALUE(B7),"–") | L7: 16
A8: 46153 | B8: 08:30 | C8: 17:30 | D8: SAL-COURS-02 | E8: Formation continue | F8: Didactique J1 | G8: Pr. Morin | H8: FC-DID-01-2026-01 | I8: Prévu | K8: =IF(AND(C8<>"",B8<>""),TIMEVALUE(C8)-TIMEVALUE(B8),"–") | L8: 40
A9: 46154 | B9: 08:30 | C9: 17:30 | D9: SAL-COURS-02 | E9: Formation continue | F9: Didactique J2 | G9: Pr. Morin | H9: FC-DID-01-2026-01 | I9: Prévu | K9: =IF(AND(C9<>"",B9<>""),TIMEVALUE(C9)-TIMEVALUE(B9),"–") | L9: 40

Sheet DEPENSES
A1: Date_Dépense | B1: Code_Session | C1: Nature_Dépense | D1: Montant (FCFA) | E1: Fournisseur/Bénéficiaire | F1: Mode_Paiement | G1: Justificatif | H1: Source_Financement | I1: Exercice_Budgétaire | J1: Validé_par
A2: 46032 | B2: FI-INF-01-2026-S1 | C2: Supports pédagogiques | D2: 85000 | E2: Imprimerie Centrale | F2: Virement | G2: FAC-2026-001 | H2: ODS | I2: 2026
A3: 46037 | B3: FI-AS-01-2026-S1 | C3: Matériel TP | D3: 42000 | E3: MedSupply | F3: Virement | G3: FAC-2026-002 | H3: ODS | I3: 2026
A4: 46069 | B4: FC-SIM-01-2026-01 | C4: Intervenants | D4: 45000 | E4: F006 – Leclerc A. | F4: Virement | G4: BC-2026-010 | H4: Budget EMSP | I4: 2026
A5: 46069 | B5: FC-SIM-01-2026-01 | C5: Hébergement | D5: 18000 | E5: Hôtel du Lac | F5: Virement | G5: FAC-2026-015 | H5: Budget EMSP | I5: 2026
A6: 46069 | B6: FC-SIM-01-2026-01 | C6: Transport | D6: 6500 | E6: Agence Voyage | F6: Chèque | G6: FAC-2026-016 | H6: Budget EMSP | I6: 2026
A7: 46090 | B7: FC-HYG-01-2026-01 | C7: Intervenants | D7: 24000 | E7: F003 – Bernard J. | F7: Virement | G7: BC-2026-020 | H7: Budget EMSP | I7: 2026
A8: 46090 | B8: FC-HYG-01-2026-01 | C8: Collations | D8: 4500 | E8: Traiteur Express | F8: Espèces | G8: RECU-2026-005 | H8: Budget EMSP | I8: 2026
A9: 46118 | B9: FC-GES-01-2026-01 | C9: Location matériel | D9: 12000 | E9: SimuMed | F9: Virement | G9: FAC-2026-031 | H9: Budget EMSP | I9: 2026
A10: 46118 | B10: FC-GES-01-2026-01 | C10: Intervenants | D10: 16000 | E10: F004 – Leroy C. | F10: Virement | G10: BC-2026-025 | H10: Budget EMSP | I10: 2026
A11: 46132 | B11: HORS_SESSION | C11: Fournitures admin. | D11: 8500 | E11: Office Pro | F11: Virement | G11: FAC-2026-040 | H11: Budget EMSP | I11: 2026
C12: TOTAL | D12: =SUM(D2:D11)

Sheet BILANS
B2: PÉRIODE D'ANALYSE | E2: Date début : | F2: 46023 | G2: Date fin : | H2: 46203
B4: 1. ACTIVITÉ DE FORMATION
B5: Nombre total de sessions | D5: =COUNTA(SESSIONS!A:A)-1
B6: Sessions – Formation initiale | D6: =COUNTIF(SESSIONS!J:J,"Planifiée")+COUNTIF(SESSIONS!J:J,"En cours")+COUNTIF(SESSIONS!J:J,"Terminée")
B7: Sessions terminées | D7: =COUNTIF(SESSIONS!J:J,"Terminée")
B8: Sessions en cours | D8: =COUNTIF(SESSIONS!J:J,"En cours")
B9: Sessions planifiées | D9: =COUNTIF(SESSIONS!J:J,"Planifiée")
B10: Total participants prévus | D10: =SUM(SESSIONS!G:G)
B11: Total participants réels | D11: =SUM(SESSIONS!H:H)
B12: Taux global de réalisation (%) | D12: =IF(SUM(SESSIONS!G:G)=0,"–",SUM(SESSIONS!H:H)/SUM(SESSIONS!G:G))
B13: Sessions Formation Initiale | D13: =COUNTIF(PARAM_FORMATIONS!C:C,"Initiale")
B14: Sessions Formation Continue | D14: =COUNTIF(PARAM_FORMATIONS!C:C,"Continue")
B16: 2. BILAN FINANCIER
B17: Nature de dépense | D17: Montant (FCFA) | E17: % du total
B18: Intervenants | D18: =SUMIF(DEPENSES!C:C,B18,DEPENSES!D:D) | E18: =IF(D27=0,"–",D18/D27)
B19: Supports pédagogiques | D19: =SUMIF(DEPENSES!C:C,B19,DEPENSES!D:D) | E19: =IF(D27=0,"–",D19/D27)
B20: Matériel TP | D20: =SUMIF(DEPENSES!C:C,B20,DEPENSES!D:D) | E20: =IF(D27=0,"–",D20/D27)
B21: Hébergement | D21: =SUMIF(DEPENSES!C:C,B21,DEPENSES!D:D) | E21: =IF(D27=0,"–",D21/D27)
B22: Transport | D22: =SUMIF(DEPENSES!C:C,B22,DEPENSES!D:D) | E22: =IF(D27=0,"–",D22/D27)
B23: Collations | D23: =SUMIF(DEPENSES!C:C,B23,DEPENSES!D:D) | E23: =IF(D27=0,"–",D23/D27)
B24: Location matériel | D24: =SUMIF(DEPENSES!C:C,B24,DEPENSES!D:D) | E24: =IF(D27=0,"–",D24/D27)
B25: Fournitures admin. | D25: =SUMIF(DEPENSES!C:C,B25,DEPENSES!D:D) | E25: =IF(D27=0,"–",D25/D27)
B26: Autre | D26: =SUMIF(DEPENSES!C:C,B26,DEPENSES!D:D) | E26: =IF(D27=0,"–",D26/D27)
B27: TOTAL | D27: =SUM(D18:D26)
B29: 3. BILAN RH – FORMATEURS
B30: Nombre total de formateurs | D30: =COUNTA(FORMATEURS_RH!A:A)-1
B31: Formateurs – Interne EMSP | D31: =COUNTIF(FORMATEURS_RH!D:D,"Interne EMSP")
B32: Formateurs – Intervenant externe | D32: =COUNTIF(FORMATEURS_RH!D:D,"Intervenant externe")
B33: Formateurs – Expert projet | D33: =COUNTIF(FORMATEURS_RH!D:D,"Expert projet")
B34: Formateurs – Enseignant UDC | D34: =COUNTIF(FORMATEURS_RH!D:D,"Enseignant UDC")
B35: Niveau Master | D35: =COUNTIF(FORMATEURS_RH!F:F,"Master")
B36: Niveau Doctorat | D36: =COUNTIF(FORMATEURS_RH!F:F,"Doctorat")
B37: Volume total d'heures (période) | D37: =SUMPRODUCT((INTERVENTIONS!E2:E500))
B40: 4. HEURES D'INTERVENTION PAR FORMATEUR – S1 2026
B41: Code_Formateur | C41: Nom | D41: Prénom | E41: Statut | F41: Discipline | G41: Heures S1
B42: F001 | C42: CHABRUT | D42: Luc | E42: Interne EMSP | F42: Soins infirmiers | G42: =SUMIF(INTERVENTIONS!C:C,B42,INTERVENTIONS!E:E)
B43: F002 | C43: MARTIN | D43: Sophie | E43: Interne EMSP | F43: Pédagogie | G43: =SUMIF(INTERVENTIONS!C:C,B43,INTERVENTIONS!E:E)
B44: F003 | C44: BERNARD | D44: Jean | E44: Interne EMSP | F44: Hygiène hospitalière | G44: =SUMIF(INTERVENTIONS!C:C,B44,INTERVENTIONS!E:E)
B45: F004 | C45: LEROY | D45: Claire | E45: Interne EMSP | F45: Médecine d'urgence | G45: =SUMIF(INTERVENTIONS!C:C,B45,INTERVENTIONS!E:E)
B46: F005 | C46: MORIN | D46: Paul | E46: Expert projet | F46: Pédagogie médicale | G46: =SUMIF(INTERVENTIONS!C:C,B46,INTERVENTIONS!E:E)
...
