Workbook

Sheet Legende
A1: EMSP — OUTIL DE GESTION (VERSION 1)
A2: Projet | B2: Expertise France / AFD — ODS 21SANOC277
A3: Reference | B3: 2026/EAALDDDGPLDGDLS/15420 — Webcreatys SAS
A4: Perimetre | B4: Volet EMSP uniquement (GMAO ecarte). V1 sur perimetre TDR.
A5: Charte | B5: Calibri ; couleur 1F4E79 ; dates JJ/MM/AAAA ; montants KMF sans decimales.
A7: CODE DE PROVENANCE DES CHAMPS
A8: (sans marqueur) | B8: Champ exige par le TDR.
A9: (*) | B9: Initiative Webcreatys : complement pour rendre le TDR operationnel.
A10: (**) | B10: Ajout EMSP hors TDR (demande en reunion du 11/06 / notas).
A12: PRINCIPES
A13: Fichier unique | B13: Filiere et type d'inscrit = colonnes (pas de decoupage par filiere).
A14: Parametres | B14: Onglet P0 : toutes les listes deroulantes sont saisies par l'EMSP.
A15: Financier | B15: 2 colonnes Recette/Depense, sans TVA, en KMF. Categories separees. Acces reserve Compta/Direction.
A16: Sans macro | B16: 100% Excel : import CSV par RECHERCHEV ; listes deroulantes par validation.
A17: Filtres | B17: Chaque tableau dispose d'un filtre sur sa ligne d'en-tete.

Sheet P0_Parametres
A1: PARAMETRES — LISTES DE REFERENCE SAISIES PAR L'EMSP
A2: Filieres | B2: Niveaux | C2: Sections (*) | D2: Semestres | E2: Statuts_etudiant (**) | F2: Genres (*) | G2: Cat_Recettes (**) | H2: Cat_Depenses (**) | I2: Postes_budgetaires (**) | J2: Modes_paiement (*) | K2: Comptes_caisses (*) | L2: Types_salle (*) | M2: Lieux_stage (**) | N2: Annees_acad (*) | O2: Sources_financement (*) | P2: Types_document (**) | Q2: Statuts_document (*) | R2: Categories_equipement (**) | S2: Categories_doc (*) | T2: Types_ecart (*) | U2: Statuts_action (*) | V2: Etats_materiel (**) | W2: Types_besoin (**) | X2: Priorites_besoin (**) | Y2: Statuts_besoin (**) | Z2: Tarif_inscription_niveau | AA2: Tarif_inscription_KMF | AB2: Types_doc_bailleur | AC2: Types_bailleur | AD2: Statuts_bailleur | AE2: Statuts_enseignant
A3: Soins infirmiers | B3: L1 | C3: S.I | D3: S1 | E3: Actif | F3: M | G3: 70 — Prestations de services | H3: 60 — Achats et variations de stocks | I3: 602 — Achats stockés – autres approvisionnements | J3: Especes | L3: Cours | M3: CHN El-Maarouf (Moroni) | N3: 2024-2025 | O3: AFD | P3: Attestation de passage | Q3: En attente conseil | R3: Informatique | S3: Stratégique | T3: Budgétaire | U3: Non démarré | V3: Actif | W3: Matériel en panne | X3: Haute | Y3: Exprimé | Z3: L1 | AA3: 70000 | AB3: Contrat/Convention | AC3: International | AD3: Actif | AE3: Permanent
A4: Soins obstétricaux | B4: L2 | C4: S.O | D4: S2 | E4: Diplome | F4: F | G4: 74 — Subvention d'exploitation | H4: 61 — Services extérieurs | I4: 6022 — Fournitures consommables | J4: Cheque | L4: TD | M4: CHR Mitsamiouli | N4: 2025-2026 | O4: Etat comorien | P4: Bulletin | Q4: En attente delai | R4: Mobilier | S4: Médical | T4: Temporel | U4: En cours | V4: En panne | W4: Matériel manquant / absent | X4: Moyenne | Y4: En cours | Z4: L2 | AA4: 70000 | AB4: Avenant | AC4: État | AD4: Clôturé | AE4: Contractuel
A5: Imagerie médicale | B5: L3 | C5: AS | E5: Abandonne | G5: 13 — Subvention d'investissement | H5: 62 — Autres services extérieurs | I5: 6022B — Fournitures d'examens | J5: Virement | L5: TP | M5: CHR Foumbouni | O5: Ressources propres EMSP | P5: Releve de notes | Q5: Imprimable | R5: Materiel pedagogique | S5: Supports de cours | T5: Contenu de formation | U5: Atteint | V5: Hors service | W5: Consommable | X5: Basse | Y5: Satisfait | Z5: L3 | AA5: 80000 | AB5: Justificatif | AC5: Bilatéral | AD5: Suspendu | AE5: Vacataire
A6: Maintenance biomédicale | B6: Master | E6: Radie | H6: 64 — Charges de personnel | I6: 6025 — Carburant et lubrifiant (groupe électrogène) | J6: Autre | L6: Amphitheatre | M6: CHR Hombo (Anjouan) | O6: Autres donateurs | Q6: Remis | R6: Materiel medical | S6: Réglementaire / officiel | T6: Qualité | U6: En retard | V6: En maintenance | W6: Nouveau matériel | Y6: Rejeté | AB6: Autre | AC6: Multilatéral | AD6: Autre | AE6: Bénévole
A7: Aides-soignants | H7: 65 — Autres charges de gestion courante | I7: 604 — Achat d'études et de prestations de services | M7: CHR Domoni (Anjouan) | R7: Autre | S7: OMS / international | T7: Autre | U7: Abandonné | V7: Réformé | W7: Réparation | AC7: ONG / Fondation
H8: 66 — Charges financières | I8: 605 — Achat de matériel — petit matériel | M8: CHR Fomboni (Moheli) | S8: Autre | W8: Autre | AC8: Privé
H9: 67 — Charges exceptionnelles | I9: 605A — Matériel didactique et pédagogique | AC9: Autre
H10: 16 — Remboursement des dettes (168 Autres dettes) | I10: 606 — Achats non stockés de matières et fournitures
H11: 20 — Immobilisations incorporelles (208 Autres) | I11: 6061 — Eau et électricité
H12: 21 — Immobilisations corporelles | I12: 6063 — Autres (fournitures de laboratoire…)
I13: 613 — Locations
I14: 615 — Entretien et réparations
I15: 6155a — Entretien du matériel commun
I16: 616 — Primes d'assurances
I17: 6163 — Assurances automobiles
I18: 6163A — Assurances étudiantes
I19: 617 — Études et recherches / formation et recherche
I20: 617d — Appui à la publication des travaux de recherche
I21: 617 (sorties) — Frais de sorties pédagogiques
I22: 617e — Indemnité d'encadrement
I23: 618 — Divers — abonnement documentation et reprographie
I24: 6185 — Conférence et séminaire
... I62: 744 — Collectivités locales

Sheet P1_Roles
A1: ROLES ET DROITS D'ACCES DES UTILISATEURS
A2: Utilisateur / Login (**) | B2: Role (**) | C2: Modules lecture (**) | D2: Modules ecriture (**) | E2: Acces financier (O/N) (**) | F2: Admin droits (O/N) (**)
A3: direction | B3: Direction | C3: Tous | D3: Tous | E3: O | F3: O
A4: scolarite | B4: Scolarite | C4: Academique, Stages | D4: Academique, Stages | E4: N | F4: N
A5: compta | B5: Comptabilite | C5: Financier | D5: Financier | E5: O | F5: N
A6: chef_dept | B6: Chef de departement | C6: Academique, Enseignants | D6: Presences | E6: N | F6: N
A7: superadmin | B7: Super-administrateur | C7: Tous | D7: Tous | E7: O | F7: O

Sheet A1_Etudiants
A1: GESTION DES ETUDIANTS — FICHES ET INSCRIPTIONS
A2: N ordre (*) | B2: Matricule | C2: Genre (*) | D2: Nom | E2: Prenom | F2: Date naissance | G2: Lieu naissance | H2: Origine / lieu actuel (**) | I2: Niveau | J2: Filiere | K2: Section (*) | L2: Annee acad. (*) | M2: Statut (**) | N2: Date inscription | O2: Saisi par (*)
A3: 1 | B3: 76496 | D3: ABDILLAH | E3: AHAMADI | F3: 27/08/1989 | G3: BAMBAO M'TSANGA | J3: Aides-soignants | L3: 2025-2026 | M3: Inscrit | O3: import
A4: 2 | B4: 76500 | D4: ABDOU | E4: SOIMADOU OUMMILHOUDA | F4: 20/04/2008 | G4: MORONI | J4: Aides-soignants | L4: 2025-2026 | M4: Inscrit | O4: import
A5: 3 | B5: 64934 | D5: ABOUDOU | E5: FAHARDINE SAMIRA | F5: 06/10/2004 | G5: IFOUNDIHE CHAMBOIN | J5: Aides-soignants | L5: 2025-2026 | M5: Inscrit | O5: import
A6: 4 | B6: 53338 | D6: AINCHAT | E6: MDOIHOMA | F6: 15/12/1997 | G6: NDZAOUDZE MITSAMIOULI | J6: Aides-soignants | L6: 2025-2026 | M6: Inscrit | O6: import
A7: 5 | B7: 73821 | D7: ALLAOUIA | E7: AHAMADA | F7: 23/12/2005 | G7: FOUMBOUDZIVOUNI | J7: Aides-soignants | L7: 2025-2026 | M7: Inscrit | O7: import
A8: 6 | B8: 67587 | D8: AMINA | E8: ALI ABDALLAH | F8: 12/09/1999 | G8: BATSA - MITSAMIOULI | J8: Aides-soignants | L8: 2025-2026 | M8: Inscrit | O8: import
A9: 7 | B9: 70008 | D9: ASMA | E9: DJAMAL MOURCHID | F9: 20/12/1999 | G9: NDZAOUZE MITSAMIOULI | J9: Aides-soignants | L9: 2025-2026 | M9: Inscrit | O9: import
A10: 8 | B10: 73436 | D10: ASSIRIA | E10: MCHANGOUMA | F10: 28/05/2004 | G10: MNOUNGOU | J10: Aides-soignants | L10: 2025-2026 | M10: Inscrit | O10: import
A11: 9 | B11: 65358 | D11: BIBI | E11: FATIMA AHAMADA | F11: 09/08/2001 | G11: CHEZANI | J11: Aides-soignants | L11: 2025-2026 | M11: Inscrit | O11: import
A12: 10 | B12: 32872 | D12: BOINAHERI | E12: MZAOUIANI | F12: 17/03/1992 | G12: IFOUNDIHE HAMAHAMET | J12: Aides-soignants | L12: 2025-2026 | M12: Inscrit | O12: import
A13: 11 | B13: 67561 | D13: DHOUMDRATI | E13: ASMAKOU | F13: 23/03/2001 | G13: MTE D'OUZIO | J13: Aides-soignants | L13: 2025-2026 | M13: Inscrit | O13: import
A14: 12 | B14: 76498 | D14: DJASSIMI | E14: YOUSSOUF | F14: 27/11/1989 | G14: DOMONI ANJOUAN | J14: Aides-soignants | L14: 2025-2026 | M14: Inscrit | O14: import
... A32: 30 | B32: 63164 | D32: SANIA | E32: DJANFAR | F32: 22/10/2001 | G32: L'HOPITAL DE POMONI | J32: Aides-soignants | L32: 2025-2026 | M32: Inscrit | O32: import
A33: 1 | B33: 79044 | D33: ABDOURAZAK | E33: IBRAHIM | F33: 20/04/2005 | G33: MANDZA MBOUDE | I33: L1 | J33: Maintenance biomédicale | L33: 2025-2026 | M33: Inscrit | O33: import
A34: 2 | B34: 70040 | D34: ALI MROUMAIZ | E34: FAMIDA | F34: 07/07/2006 | G34: CLIMIQUE DE L'AMITIE | I34: L1 | J34: Maintenance biomédicale | L34: 2025-2026 | M34: Inscrit | O34: import
A35: 3 | B35: 76381 | D35: ANZIMATA | E35: IBRAHIMA ABDOU | F35: 19/05/2006 | G35: MTE DE MITSOUDJE | I35: L1 | J35: Maintenance biomédicale | L35: 2025-2026 | M35: Inscrit | O35: import
A36: 4 | B36: 80125 | D36: AWAD | E36: YAHAYA MOHAMED | F36: 03/12/2007 | G36: MTE DE MORONI | I36: L1 | J36: Maintenance biomédicale | L36: 2025-2026 | M36: Inscrit | O36: import
A37: 5 | B37: 76331 | D37: AYIMANE | E37: ABABACAR | F37: 24/02/2005 | G37: MTE DE DOUNIANI | I37: L1 | J37: Maintenance biomédicale | L37: 2025-2026 | M37: Inscrit | O37: import
A38: 6 | B38: 72388 | D38: AZYA | E38: BOURHANE | F38: 25/09/2002 | G38: MTE DE MORONI | I38: L1 | J38: Maintenance biomédicale | L38: 2025-2026 | M38: Inscrit | O38: import
A39: 7 | B39: 73389 | D39: FAIDA | E39: MOUHAMADI | F39: 12/05/2006 | G39: MTE SIMA ANJOUAN | I39: L1 | J39: Maintenance biomédicale | L39: 2025-2026 | M39: Inscrit | O39: import
A40: 8 | B40: 73797 | D40: FATIMA | E40: BOINA | F40: 20/02/2005 | G40: MTE RURALE D'OUZIOINI | I40: L1 | J40: Maintenance biomédicale | L40: 2025-2026 | M40: Inscrit | O40: import
A41: 9 | B41: 72845 | D41: HIMNATOU | E41: AHAMADA | F41: 27/03/2004 | G41: MTE DE MORONI | I41: L1 | J41: Maintenance biomédicale | L41: 2025-2026 | M41: Inscrit | O41: import
A42: 10 | B42: 78370 | D42: KASSIM | E42: AVOUKA MBAE | F42: 18/07/2007 | G42: DJOMANI MBOUDE | I42: L1 | J42: Maintenance biomédicale | L42: 2025-2026 | M42: Inscrit | O42: import
A43: 11 | B43: 71450 | D43: LOULOU | E43: AHAMADA | F43: 19/12/2005 | G43: HAHAYA | I43: L1 | J43: Maintenance biomédicale | L43: 2025-2026 | M43: Inscrit | O43: import
A44: 12 | B44: 69323 | D44: MOHMED | E44: SAINDOU | F44: 01/04/2002 | G44: MTE DE SIMA ANJOUAN | I44: L1 | J44: Maintenance biomédicale | L44: 2025-2026 | M44: Inscrit | O44: import
... A401: 24 | B401: 75275 | D401: FAZILA | E401: MOHAMED | F401: 25/12/2004 | G401: HAHAYA | I401: L2 | J401: Soins obstétricaux | L401: 2025-2026 | M401: Inscrit | O401: import
A402: 25 | B402: 76123 | D402: HABACHIYA_MLARAHA | F402: 20/09/2004 | G402: MTE DE MORONI | I402: L2 | J402: Soins obstétricaux | L402: 2025-2026 | M402: Inscrit | O402: import
A403: 26 | B403: 74264 | D403: HABDALLAH | E403: ALI ROUKYA | F403: 25/12/2006 | G403: FOUMBOUNI BADJINI EST | I403: L2 | J403: Soins obstétricaux | L403: 2025-2026 | M403: Inscrit | O403: import
A404: 27 | B404: 75852 | D404: HACHIMINE | E404: NAOUMANE | F404: 25/05/2005 | G404: JIMILIME - ANJOUAN | I404: L2 | J404: Soins obstétricaux | L404: 2025-2026 | M404: Inscrit | O404: import
A405: 28 | B405: 74460 | D405: HADHOIRMIA | E405: RAMADHOINI | F405: 18/09/2007 | G405: NTSOUDJINI | I405: L2 | J405: Soins obstétricaux | L405: 2025-2026 | M405: Inscrit | O405: import
A406: 29 | B406: 72476 | D406: HADIDJA | E406: MMADI MMADI | F406: 08/02/2000 | G406: MTE DE MORONI | I406: L2 | J406: Soins obstétricaux | L406: 2025-2026 | M406: Inscrit | O406: import
A407: 30 | B407: 73408 | D407: HADIDJA | E407: SAID HAMADI | F407: 10/06/2006 | G407: PIDJANI - DOMBA | I407: L2 | J407: Soins obstétricaux | L407: 2025-2026 | M407: Inscrit | O407: import
A408: 31 | B408: 72452 | D408: HADIDJA | E408: SAINDOU | F408: 21/02/2003 | G408: JIMILIME - ANJOUAN | I408: L2 | J408: Soins obstétricaux | L408: 2025-2026 | M408: Inscrit | O408: import
A409: 32 | B409: 76036 | D409: HADJIRA | E409: SAID AHAMADI | F409: 11/01/2007 | G409: MTE DE HOMBO | I409: L2 | J409: Soins obstétricaux | L409: 2025-2026 | M409: Inscrit | O409: import
A410: 33 | B410: 75926 | D410: HALIMA | E410: AHMED | F410: 22/12/2003 | G410: SAANDANI | I410: L2 | J410: Soins obstétricaux | L410: 2025-2026 | M410: Inscrit | O410: import
A411: 34 | B411: 66924 | D411: HALIMA | E411: HASSANE | F411: 25/12/1999 | G411: NIOUMADZAHA BADJINI EST | I411: L2 | J411: Soins obstétricaux | L411: 2025-2026 | M411: Inscrit | O411: import
A412: 35 | B412: 73354 | D412: HAMIDATI | E412: HASSANI | F412: 20/12/2004 | G412: SIMAMBOINI B/EST | I412: L2 | J412: Soins obstétricaux | L412: 2025-2026 | M412: Inscrit | O412: import
A413: 36 | B413: 75944 | D413: HIDMATILLAH | E413: SAINDOU | F413: 31/08/2005 | G413: L' HOPITAL DE TSEMBEHOU ANJOUAN | I413: L2 | J413: Soins obstétricaux | L413: 2025-2026 | M413: Inscrit | O413: import
...

Sheet A2_Presences
A1: PRESENCES DES ETUDIANTS — PAR CRENEAU HORAIRE
A2: Date (**) | B2: Matricule (**) | C2: Session / Matiere (**) | D2: Creneau (**) | E2: Present (O/N) (**) | F2: Saisi par (*)
A3: 01/07/2026 | B3: 76496 | C3: Aides-soignants - Test matiere | D3: 10:00-12:00 | E3: N | F3: superadmin
A4: 01/07/2026 | B4: 76500 | C4: Aides-soignants - Test matiere | D4: 10:00-12:00 | E4: N | F4: superadmin
A5: 01/07/2026 | B5: 64934 | C5: Aides-soignants - Test matiere | D5: 10:00-12:00 | E5: N | F5: superadmin
A6: 01/07/2026 | B6: 53338 | C6: Aides-soignants - Test matiere | D6: 10:00-12:00 | E6: N | F6: superadmin
A7: 01/07/2026 | B7: 73821 | C7: Aides-soignants - Test matiere | D7: 10:00-12:00 | E7: N | F7: superadmin
A8: 01/07/2026 | B8: 67587 | C8: Aides-soignants - Test matiere | D8: 10:00-12:00 | E8: N | F8: superadmin
A9: 01/07/2026 | B9: 70008 | C9: Aides-soignants - Test matiere | D9: 10:00-12:00 | E9: N | F9: superadmin
A10: 01/07/2026 | B10: 73436 | C10: Aides-soignants - Test matiere | D10: 10:00-12:00 | E10: N | F10: superadmin
A11: 01/07/2026 | B11: 65358 | C11: Aides-soignants - Test matiere | D11: 10:00-12:00 | E11: N | F11: superadmin
A12: 01/07/2026 | B12: 32872 | C12: Aides-soignants - Test matiere | D12: 10:00-12:00 | E12: N | F12: superadmin
A13: 01/07/2026 | B13: 67561 | C13: Aides-soignants - Test matiere | D13: 10:00-12:00 | E13: N | F13: superadmin
... A32: 01/07/2026 | B32: 63164 | C32: Aides-soignants - Test matiere | D32: 10:00-12:00 | E32: N | F32: superadmin

Sheet A3_Sessions
A1: SEANCES ET PLANNING — MATIERES, ENSEIGNANTS, SALLES
A2: ID session | B2: Annee acad. (*) | C2: Semestre | D2: Filiere | E2: Niveau | F2: Section (*) | G2: Matiere | H2: Enseignant | I2: Salle | J2: Jour | K2: Heure debut | L2: Heure fin | M2: Type (*) | N2: Vol. horaire prog. (*)
A3: S001 | B3: 2025-2026 | C3: 1 | D3: Soins infirmiers | E3: L1 | F3: S.I | G3: Microbiologie | H3: Dr EL HABIB | J3: Jeudi | K3: 10h05 | L3: 12h05 | N3: 30
A4: S002 | B4: 2025-2026 | C4: 1 | D4: Soins infirmiers | E4: L1 | F4: S.I | G4: Besoins fondamentaux du patient | H4: Mme Zainaba Mohamed | J4: Jeudi | K4: 13h00 | L4: 15h00 | N4: 2
A5: S003 | B5: 2025-2026 | C5: 1 | D5: Soins infirmiers | E5: L1 | F5: S.I | G5: Démarche de soins et Projet de soins | J5: Jeudi | K5: 13h00 | L5: 15h00 | N5: 2
A6: S004 | B6: 2025-2026 | C6: 1 | D6: Soins infirmiers | E6: L1 | F6: S.I | G6: Généralité sur la SP/SC | H6: Anne Beugny | J6: Jeudi | K6: 13h00 | L6: 15h00 | N6: 8
A7: S005 | B7: 2025-2026 | C7: 1 | D7: Soins infirmiers | E7: L1 | F7: S.I | G7: Liquides et életrolytes | J7: Jeudi | K7: 13h00 | L7: 15h00 | N7: 4
A8: S006 | B8: 2025-2026 | C8: 1 | D8: Soins infirmiers | E8: L1 | F8: S.I | G8: Procédure d’admission | J8: Jeudi | K8: 13h00 | L8: 15h00 | N8: 4
A9: S007 | B9: 2025-2026 | C9: 1 | D9: Soins infirmiers | E9: L1 | F9: S.I | G9: Système cardiovasculaire | J9: Jeudi | K9: 13h00 | L9: 15h00 | N9: 2
A10: S008 | B10: 2025-2026 | C10: 1 | D10: Soins infirmiers | E10: L1 | F10: S.I | G10: TD Besoins fondamentaux du patient | J10: Jeudi | K10: 13h00 | L10: 15h00 | N10: 6
A11: S009 | B11: 2025-2026 | C11: 1 | D11: Soins infirmiers | E11: L1 | F11: S.I | G11: TD Démarche de soins et Projet de soins | J11: Jeudi | K11: 13h00 | L11: 15h00 | N11: 2
A12: S010 | B12: 2025-2026 | C12: 1 | D12: Soins infirmiers | E12: L1 | F12: S.I | G12: Epidémiologie | J12: Jeudi | K12: 15h05 | L12: 17h05 | N12: 2
A13: S011 | B13: 2025-2026 | C13: 1 | D13: Soins infirmiers | E13: L1 | F13: S.I | G13: Examens de laboratoire | J13: Jeudi | K13: 15h05 | L13: 17h05 | N13: 10
A14: S012 | B14: 2025-2026 | C14: 1 | D14: Soins infirmiers | E14: L1 | F14: S.I | G14: Généralités sur la pharmacologie | J14: Jeudi | K14: 15h05 | L14: 17h05 | N14: 8
A15: S013 | B15: 2025-2026 | C15: 1 | D15: Soins infirmiers | E15: L1 | F15: S.I | G15: Methodes statistiques | J15: Jeudi | K15: 15h05 | L15: 17h05 | N15: 4
A16: S014 | B16: 2025-2026 | C16: 1 | D16: Soins infirmiers | E16: L1 | F16: S.I | G16: Système cardiovasculaire | J16: Jeudi | K16: 15h05 | L16: 17h05 | N16: 4
A17: S015 | B17: 2025-2026 | C17: 1 | D17: Soins infirmiers | E17: L1 | F17: S.I | G17: TD Généralités sur la pharmacologie | J17: Jeudi | K17: 15h05 | L17: 17h05 | N17: 2
A18: S016 | B18: 2025-2026 | C18: 1 | D18: Soins infirmiers | E18: L1 | F18: S.I | G18: Anatomie du système digestif | J18: Jeudi | K18: 8h00 | L18: 10h00 | N18: 2
... A20: S018 | B20: 2025-2026 | C20: 1 | D20: Soins infirmiers | E20: L1 | F20: S.I | G20: Anatomie du système Respiratoire | J20: Lundi | K20: 10h05 | L20: 12h05 | N20: 2
A21: S019 | B21: 2025-2026 | C21: 1 | D21: Soins infirmiers | E21: L1 | F21: S.I | G21: Anatomie du système endocrinien | H21: Moussa Mohamed Ahmed (Chef de département formation continue et santé publique) | J21: Lundi | K21: 10h05 | L21: 12h05 | N21: 4
A22: S020 | B22: 2025-2026 | C22: 1 | D22: Soins infirmiers | E22: L1 | F22: S.I | G22: Anatomie du système nerveux | J22: Lundi | K22: 10h05 | L22: 12h05 | N22: 4
A23: S021 | B23: 2025-2026 | C23: 1 | D23: Soins infirmiers | E23: L1 | F23: S.I | G23: Appareil locomoteur | J23: Lundi | K23: 10h05 | L23: 12h05 | N23: 2
A24: S022 | B24: 2025-2026 | C24: 1 | D24: Soins infirmiers | E24: L1 | F24: S.I | G24: Sémiologie médicochirurgicale | J24: Lundi | K24: 10h05 | L24: 12h05 | N24: 14
A25: S023 | B25: 2025-2026 | C25: 1 | D25: Soins infirmiers | E25: L1 | F25: S.I | G25: TD Disposition d’un environnement sûr | J25: Lundi | K25: 10h05 | L25: 12h05 | N25: 2
A26: S024 | B26: 2025-2026 | C26: 1 | D26: Soins infirmiers | E26: L1 | F26: S.I | G26: Anatomie des organes de sens | H26: Irina Ismaïla Abdou | J26: Lundi | K26: 13h00 | L26: 15h00 | N26: 4
A27: S025 | B27: 2025-2026 | C27: 1 | D27: Soins infirmiers | E27: L1 | F27: S.I | G27: Démographie | J27: Lundi | K27: 13h00 | L27: 15h00 | N27: 14
A28: S026 | B28: 2025-2026 | C28: 1 | D28: Soins infirmiers | E28: L1 | F28: S.I | G28: L’infirmier dans l’environnement sanitaire | J28: Lundi | K28: 13h00 | L28: 15h00 | N28: 2
A29: S027 | B29: 2025-2026 | C29: 1 | D29: Soins infirmiers | E29: L1 | F29: S.I | G29: Perceptions en matière de santé | H29: Mréha Abdou (Chef de département S.O) | J29: Lundi | K29: 13h00 | L29: 15h00 | N29: 2
A30: S028 | B30: 2025-2026 | C30: 1 | D30: Soins infirmiers | E30: L1 | F30: S.I | G30: TD Disposition d’un environnement sûr | J30: Lundi | K30: 13h00 | L30: 15h00 | N30: 4
A31: S029 | B31: 2025-2026 | C31: 1 | D31: Soins infirmiers | E31: L1 | F31: S.I | G31: TD Perceptions en matière de santé | J31: Lundi | K31: 13h00 | L31: 15h00 | N31: 2
A32: S030 | B32: 2025-2026 | C32: 1 | D32: Soins infirmiers | E32: L1 | F32: S.I | G32: Appareil urogénital | J32: Lundi | K32: 15h05 | L32: 17h05 | N32: 8
A33: S031 | B33: 2025-2026 | C33: 1 | D33: Soins infirmiers | E33: L1 | F33: S.I | G33: Communication | J33: Lundi | K33: 15h05 | L33: 17h05 | N33: 10
A34: S032 | B34: 2025-2026 | C34: 1 | D34: Soins infirmiers | E34: L1 | F34: S.I | G34: Epidémiologie | J34: Lundi | K34: 15h05 | L34: 17h05 | N34: 2
A35: S033 | B35: 2025-2026 | C35: 1 | D35: Soins infirmiers | E35: L1 | F35: S.I | G35: Methodes statistiques | J35: Lundi | K35: 15h05 | L35: 17h05 | N35: 2
A36: S034 | B36: 2025-2026 | C36: 1 | D36: Soins infirmiers | E36: L1 | F36: S.I | G36: Sémiologie médicochirurgicale | J36: Lundi | K36: 15h05 | L36: 17h05 | N36: 2
A37: S035 | B37: 2025-2026 | C37: 1 | D37: Soins infirmiers | E37: L1 | F37: S.I | G37: TD Théories, modèles et interaction | J37: Lundi | K37: 15h05 | L37: 17h05 | N37: 2
A38: S036 | B38: 2025-2026 | C38: 1 | D38: Soins infirmiers | E38: L1 | F38: S.I | G38: Théories, modèles et interaction | J38: Lundi | K38: 15h05 | L38: 17h05 | N38: 2
A39: S037 | B39: 2025-2026 | C39: 1 | D39: Soins infirmiers | E39: L1 | F39: S.I | G39: Anatomie des organes de sens | H39: Irina Ismaïla Abdou | J39: Lundi | K39: 8h00 | L39: 10h00 | N39: 4
A40: S038 | B40: 2025-2026 | C40: 1 | D40: Soins infirmiers | E40: L1 | F40: S.I | G40: Contrôle Anatomie du système Respiratoire et digestif | J40: Lundi | K40: 8h00 | L40: 10h00 | N40: 2
A41: S039 | B41: 2025-2026 | C41: 1 | D41: Soins infirmiers | E41: L1 | F41: S.I | G41: Contrôle Généralités sur la pharmacologie | J41: Lundi | K41: 8h00 | L41: 10h00 | N41: 2
...

Sheet A4_Documents_etud
A1: DOCUMENTS ETUDIANTS — ATTESTATIONS ET BULLETINS
A2: Matricule (**) | B2: Type de document (**) | C2: Annee concernee (**) | D2: Date generation (**) | E2: Statut (*) | F2: Date liberation (*) | G2: Remis le (**)

Sheet S1_Stages
A1: STAGES — AFFECTATION ET FICHES DE RETOUR
A2: Matricule (*) | B2: Annee acad. (*) | C2: N seance (1-6) (*) | D2: Lieu de stage (*) | E2: Date debut (*) | F2: Date fin (*) | G2: Fiche retour (O/N) (*) | H2: Note stage /20 (*) | I2: Observation / plainte (**) | J2: Session | K2: Heures d'absence (**)

Sheet E1_Enseignants
A1: ENSEIGNANTS ET VACATAIRES — FICHES
A2: Matricule ens. | B2: Genre (*) | C2: Nom | D2: Prenom | E2: Statut (*) | F2: Matieres enseignees | G2: Qualifications (*) | H2: Departement | I2: Chef dept validant (*) | J2: Taux horaire (KMF/h) | K2: Mode de remuneration | L2: Cout mensuel (KMF)
A3: ENS-001 | C3: Adamou Hamada Jean Alain | E3: Permanent | F3: Obstétrique normale; Soins obstétricaux d’urgence de base (SONUB); Anatomie de l'Appareil urinaire; Anatomie système génitale; Pathologies de la grossesse et du travail; Pathologie de l’accouchement et Des suites de couches; Pathologies gynécologiques; Aspiration Manuelle IntraUtérine (AMIU); Ventouse et Forceps
A4: ENS-002 | C4: Daniel Ali Soumaïla (Chef de département S.I) | E4: Permanent | F4: Premiers secours et soins d’urgence; Théories, modèles et interaction; Personne agonisant et decedé; PCIME dr Zoubeir; PCIME; Gestion des catastrophes/Fléaux sociaux
A5: ENS-003 | C5: Dr EL HABIB | E5: Permanent | F5: Microbiologie, micro-organismes et parasitologie; introduction à la biochimie (prévoir des TD de biochimie); Communication interpersonnel (a chercher DSPP)); ethique et déontologie; cancerologie dr widad
A6: ENS-004 | C6: Dr Kamal Ahamada (Directeur) | E6: Permanent | F6: Chirurgie pédiatrique; Methodologie de recherche; introduction à la recherche; Introduction au corps humain (Dr Mbae); Affections urologiques; Urgences traumatologiques; Soutenance un travail de fin d’études; Pathologies et grossesses; Anatomie du bassin et du périnée
A7: ENS-005 | C7: HALIMA ABDALLAH | E7: Permanent | F7: Santé sexuelle et reproductive et droits connexes; Vaccination; TD/:TP des programme; Stratégies conventionnelles et novatrices de communication; Gestion des services de santé; Démographie en SRMNIA; S.I Stomatologies; Soins gynéco-obstétricaux de base; Soins obstétricaux; Planification familiale et technologie contraceptive,
A8: ENS-006 | C8: Irina Ismaïla Abdou | E8: Permanent | F8: Sémiologie Médical; Pathologies dermatologiques; Anatomie du système digestif; Anatomie du système cardiovasculaire et sang; Hématopoïèse; Anatomie des organes de sens; Pathologies digestifs; Gynécologie; Sémiologie gynécologique; sémiologie chirurgicale; Gériatrie; Troubless psychiatriques; Troisième âge, Andropause et Ménopause; Consultations des enfants sains
A9: ENS-007 | C9: Mme Houzaimata Ahamada | E9: Permanent | F9: Introduction à la psychologie; Psychologie de l’enfant; prise en charge Psychologie des enfants victimes ou tentatives d'agression; Prise en charge Psychologie des agressions physique et psychologiques couple; Psychologie; Psychologie de la femme enceinte; S.I Affections neurologiques
A10: ENS-008 | C10: Mohamed Ibrahim Kaïva | E10: Permanent | F10: Sociologie; Antropologie de la santé; Anthropologie
A11: ENS-009 | C11: Moussa Hasane (a contacter) | E11: Permanent | F11: Communication virtuelle
A12: ENS-010 | C12: Moussa Mohamed Ahmed (Chef de département formation continue et santé publique) | E12: Permanent | F12: Pathologies endocriniennes; Anatomie du Système Endocrinien; Anatomie systèmes respiratoire; Systèmes d’intégration, de protection et de contrôle nerveux, endocrine; L’infection, la résistance de l’hôte et le contrôle des infections; Maladies infectieuses, parasitaires et VIH; Affections respiratoires; Affections neurologiques
A13: ENS-011 | C13: Mr Daniel Ali (Chef de Département S.I) | E13: Permanent | F13: Base théorique des soins infirmiers en milieu communautaire; Maladies transmissibles : prévention et intervention; Santé familiale; Soins à domicile, en milieu communautaire et soins palliatifs; Soins infirmiers en médecine de Catastrophe; Soins infirmiers en médecine de travail; Santé scolaire
A14: ENS-012 | C14: Mréha Abdou (Chef de département S.O) | E14: Permanent | F14: Infirmier dans l'environnement sanitaire; Perceptions en matière de santé; Disposition d'un environnement sûr; Prévention et contrôle des infections; Calcul des doses médicamenteuses; S.I en urgences et réanimation
... A54: ENS-052 | C54: Soudjay Asnounat | E54: Vacataire | F54: Protocoles de prise en charge de la grossesse normale (calendrier et objectifs, prestations biologiques, cliniques et radiologiques); Préparation à l’accouchement normal; Protocoles de prise en charge en post Partum immédiat et précoce; Physiologie des trois stades de l’accouchement

Sheet E2_Releve_heures
A1: RELEVE DES HEURES ENSEIGNANTS — POUR LA PAIE
A2: Mois / Annee (*) | B2: Matricule ens. (*) | C2: Vol. horaire prog. (*) | D2: Vol. horaire constate (*) | E2: Total heures a payer (*)
E3: =IF(D3="","",D3)
E4: =IF(D4="","",D4)
E5: =IF(D5="","",D5)
E6: =IF(D6="","",D6)
E7: =IF(D7="","",D7)
E8: =IF(D8="","",D8)
E9: =IF(D9="","",D9)
E10: =IF(D10="","",D10)
E11: =IF(D11="","",D11)
E12: =IF(D12="","",D12)
E13: =IF(D13="","",D13)
E14: =IF(D14="","",D14)
... E300: =IF(D300="","",D300)

Sheet L1_Salles
A1: SALLES — DESCRIPTIF ET EQUIPEMENTS
A2: ID salle | B2: Nom / libelle | C2: Type (*) | D2: Capacite | E2: Equipements (*) | F2: Batiment / localisation (*)
A3: SC02 | B3: Salle de cours N°2 | C3: Cours | D3: 37
A4: SC04 | B4: Salle de cours N°4 | C4: Cours | D4: 86
A5: SC06 | B5: Salle de cours N°6 | C5: Cours | D5: 87
A6: SC07 | B6: Salle de cours N°7 | C6: Cours | D6: 19
A7: SC08 | B7: Salle de cours N°8 | C7: Cours | D7: 25
A8: SC09 | B8: Salle de cours N°9 | C8: Cours | D8: 50
A9: SC10 | B9: Salle de cours N°10 | C9: Cours | D9: 74
A10: TP1 | B10: Salle de TP — Simulation néonatologie | C10: TP
A11: TP2 | B11: Salle de TP — Simulation pédiatrie | C11: TP
A12: TP3 | B12: Salle de TP — LMS | C12: TP
A13: TP4 | B13: Salle de TP — Urgences réanimation | C13: TP
A14: TP5 | B14: Salle de TP — Simulation accouchement | C14: TP
A15: TP6 | B15: Salle de TP — Simulation hémorragies gynéco-obstétrique | C15: TP
A16: TP7 | B16: Salle de TP — Soins de base | C16: TP
A17: TP0 | B17: Salle de TP (à ventiler) | C17: TP
A18: SINFO | B18: Salle d'informatique | C18: Spécialisée | D18: 42
A19: SCONF | B19: Salle des conférences | C19: Spécialisée
A20: SREPRO | B20: Salle de reprographie | C20: Spécialisée
A21: SPROF | B21: Salle des profs | C21: Spécialisée
A22: B-DIR | B22: Bureau de la Direction | C22: Bureau
A23: B-DIRADJ | B23: Bureau du Directeur adjoint | C23: Bureau
A24: B-GEST | B24: Bureau du Gestionnaire | C24: Bureau
A25: B-AUF | B25: Bureau AUF | C25: Bureau
A26: B-ASSDIR | B26: Bureau de l'Assistant de direction | C26: Bureau
A27: B-SECR | B27: Bureau du Secrétariat | C27: Bureau
A28: B-AGSCO | B28: Bureau des Agents de scolarité | C28: Bureau
A29: B-CHSCO | B29: Bureau du Chef de la scolarité | C29: Bureau
A30: B-DSI | B30: Bureau du Chef de département Soins infirmiers | C30: Bureau
... A33: DIV-MOB | B33: Mobiliers de bureau (non localisé) | C33: Divers

Sheet F1_Mouvements
A1: TRESORERIE — RECETTES ET DEPENSES (KMF)
A2: Date operation | B2: Sens (*) | C2: Categorie (**) | D2: Poste budgetaire (**) | E2: Mode paiement (*) | F2: Compte / caisse (*) | G2: Reference / N piece (*) | H2: Libelle / description | I2: Montant Recette (KMF) | J2: Montant Depense (KMF) | K2: Tiers (*) | L2: Statut (*) | M2: Date echeance (*) | N2: Date reglement (*) | O2: Saisi par (*) | P2: Source de financement / Bailleur (*) | Q2: Compte (**) | R2: Matricule | S2: Annee academique (*)

Sheet F2_Comptes
A1: COMPTES ET CAISSES — SOLDES
A2: Nom du compte / caisse (*) | B2: Type (*) | C2: Solde initial (KMF) (*) | D2: Solde courant (KMF) (*)
A3: Compte bancaire UDC-EMSP-ODS (BIC-Comores) | B3: Banque | D3: =IF(A3="","",C3+SUMIF(F1_Mouvements!$F$3:$F$50000,A3,F1_Mouvements!$I$3:$I$50000)-SUMIF(F1_Mouvements!$F$3:$F$50000,A3,F1_Mouvements!$J$3:$J$50000))
A4: Caisse EMSP | B4: Caisse | D4: =IF(A4="","",C4+SUMIF(F1_Mouvements!$F$3:$F$50000,A4,F1_Mouvements!$I$3:$I$50000)-SUMIF(F1_Mouvements!$F$3:$F$50000,A4,F1_Mouvements!$J$3:$J$50000))
D5: =IF(A5="","",C5+SUMIF(F1_Mouvements!$F$3:$F$50000,A5,F1_Mouvements!$I$3:$I$50000)-SUMIF(F1_Mouvements!$F$3:$F$50000,A5,F1_Mouvements!$J$3:$J$50000))
D6: =IF(A6="","",C6+SUMIF(F1_Mouvements!$F$3:$F$50000,A6,F1_Mouvements!$I$3:$I$50000)-SUMIF(F1_Mouvements!$F$3:$F$50000,A6,F1_Mouvements!$J$3:$J$50000))
D7: =IF(A7="","",C7+SUMIF(F1_Mouvements!$F$3:$F$50000,A7,F1_Mouvements!$I$3:$I$50000)-SUMIF(F1_Mouvements!$F$3:$F$50000,A7,F1_Mouvements!$J$3:$J$50000))
D8: =IF(A8="","",C8+SUMIF(F1_Mouvements!$F$3:$F$50000,A8,F1_Mouvements!$I$3:$I$50000)-SUMIF(F1_Mouvements!$F$3:$F$50000,A8,F1_Mouvements!$J$3:$J$50000))
D9: =IF(A9="","",C9+SUMIF(F1_Mouvements!$F$3:$F$50000,A9,F1_Mouvements!$I$3:$I$50000)-SUMIF(F1_Mouvements!$F$3:$F$50000,A9,F1_Mouvements!$J$3:$J$50000))
D10: =IF(A10="","",C10+SUMIF(F1_Mouvements!$F$3:$F$50000,A10,F1_Mouvements!$I$3:$I$50000)-SUMIF(F1_Mouvements!$F$3:$F$50000,A10,F1_Mouvements!$J$3:$J$50000))
D11: =IF(A11="","",C11+SUMIF(F1_Mouvements!$F$3:$F$50000,A11,F1_Mouvements!$I$3:$I$50000)-SUMIF(F1_Mouvements!$F$3:$F$50000,A11,F1_Mouvements!$J$3:$J$50000))
D12: =IF(A12="","",C12+SUMIF(F1_Mouvements!$F$3:$F$50000,A12,F1_Mouvements!$I$3:$I$50000)-SUMIF(F1_Mouvements!$F$3:$F$50000,A12,F1_Mouvements!$J$3:$J$50000))
D13: =IF(A13="","",C13+SUMIF(F1_Mouvements!$F$3:$F$50000,A13,F1_Mouvements!$I$3:$I$50000)-SUMIF(F1_Mouvements!$F$3:$F$50000,A13,F1_Mouvements!$J$3:$J$50000))
D14: =IF(A14="","",C14+SUMIF(F1_Mouvements!$F$3:$F$50000,A14,F1_Mouvements!$I$3:$I$50000)-SUMIF(F1_Mouvements!$F$3:$F$50000,A14,F1_Mouvements!$J$3:$J$50000))
D15: =IF(A15="","",C15+SUMIF(F1_Mouvements!$F$3:$F$50000,A15,F1_Mouvements!$I$3:$I$50000)-SUMIF(F1_Mouvements!$F$3:$F$50000,A15,F1_Mouvements!$J$3:$J$50000))
D16: =IF(A16="","",C16+SUMIF(F1_Mouvements!$F$3:$F$50000,A16,F1_Mouvements!$I$3:$I$50000)-SUMIF(F1_Mouvements!$F$3:$F$50000,A16,F1_Mouvements!$J$3:$J$50000))
... D51: =IF(A51="","",C51+SUMIF(F1_Mouvements!$F$3:$F$50000,A51,F1_Mouvements!$I$3:$I$50000)-SUMIF(F1_Mouvements!$F$3:$F$50000,A51,F1_Mouvements!$J$3:$J$50000))

Sheet G1_Plan_action
A1: PLAN D'ACTION — SUIVI DES ECARTS ET AXES DE PROGRES
A2: N | B2: Domaine / module | C2: Ecart constate | D2: Action corrective | E2: Responsable | F2: Echeance | G2: Statut | H2: Type d'écart | I2: Axe / thème | J2: Objectif (résultat attendu) | K2: Priorité | L2: Temporalité | M2: Indicateur de réussite et preuves | N2: Observations

Sheet H1_Biblio_docs
A1: BIBLIOTHEQUE DES DOCUMENTS OFFICIELS
A2: Titre du document (**) | B2: Type (**) | C2: Reference (**) | D2: Chemin / lien local (*) | E2: Date de mise a jour (**) | F2: Responsable mise a jour (**)

Sheet TDB_Direction
A1: TABLEAU DE BORD — DIRECTION (lecture seule)
A3: ACTIVITE | D3: FINANCE (KMF)
A4: Effectif total etudiants | B4: =COUNTA(A1_Etudiants!$B$3:$B$50000) | D4: Total recettes | E4: =SUM(F1_Mouvements!$I$3:$I$50000)
A5: Dont actifs | B5: =COUNTIF(A1_Etudiants!$M$3:$M$50000,"Actif") | D5: Total depenses | E5: =SUM(F1_Mouvements!$J$3:$J$50000)
A6: Dont diplomes | B6: =COUNTIF(A1_Etudiants!$M$3:$M$50000,"Diplome") | D6: Solde global | E6: =E4-E5
A7: Dont abandonnes | B7: =COUNTIF(A1_Etudiants!$M$3:$M$50000,"Abandonne")
A8: Dont radies | B8: =COUNTIF(A1_Etudiants!$M$3:$M$50000,"Radie")
A10: EFFECTIF PAR FILIERE | D10: RH FORMATEURS
A11: =IF(P0_Parametres!A3="","",P0_Parametres!A3) | B11: =IF(P0_Parametres!A3="","",COUNTIF(A1_Etudiants!$J$3:$J$50000,P0_Parametres!A3)) | D11: Total heures constatees | E11: =SUM(E2_Releve_heures!$D$3:$D$50000)
A12: =IF(P0_Parametres!A4="","",P0_Parametres!A4) | B12: =IF(P0_Parametres!A4="","",COUNTIF(A1_Etudiants!$J$3:$J$50000,P0_Parametres!A4)) | D12: Nb enseignants references | E12: =COUNTA(E1_Enseignants!$A$3:$A$50000)
A13: =IF(P0_Parametres!A5="","",P0_Parametres!A5) | B13: =IF(P0_Parametres!A5="","",COUNTIF(A1_Etudiants!$J$3:$J$50000,P0_Parametres!A5))
A14: PRESENCE | B14: =IF(P0_Parametres!A6="","",COUNTIF(A1_Etudiants!$J$3:$J$50000,P0_Parametres!A6))
A15: Taux de presence global | B15: =IFERROR(COUNTIF(A2_Presences!$E$3:$E$50000,"O")/COUNTA(A2_Presences!$E$3:$E$50000),0)
A16: =IF(P0_Parametres!A8="","",P0_Parametres!A8) | B16: =IF(P0_Parametres!A8="","",COUNTIF(A1_Etudiants!$J$3:$J$50000,P0_Parametres!A8))
A17: =IF(P0_Parametres!A9="","",P0_Parametres!A9) | B17: =IF(P0_Parametres!A9="","",COUNTIF(A1_Etudiants!$J$3:$J$50000,P0_Parametres!A9))
A18: =IF(P0_Parametres!A10="","",P0_Parametres!A10) | B18: =IF(P0_Parametres!A10="","",COUNTIF(A1_Etudiants!$J$3:$J$50000,P0_Parametres!A10))

Sheet Dictionnaire
A1: DICTIONNAIRE DES DONNEES — EMSP V1
A2: Onglet | B2: Champ | C2: Type | D2: Obligatoire | E2: Provenance | F2: Liste / source | G2: Description
A3: P0_Parametres | B3: Filieres | C3: Texte | D3: Oui | E3: TDR | F3: - | G3: Libelles des filieres saisis par l'EMSP (5 actuellement).
A4: P0_Parametres | B4: Niveaux | C4: Texte | D4: Oui | E4: TDR | F4: - | G4: L1, L2, L3, Master (modifiable).
A5: P0_Parametres | B5: Sections | C5: Texte | D5: Non | E5: Initiative (*) | F5: - | G5: S.I, S.O, AS (modifiable).
A6: P0_Parametres | B6: Semestres | C6: Texte | D6: Oui | E6: TDR | F6: - | G6: S1, S2.
A7: P0_Parametres | B7: Statuts_etudiant | C7: Texte | D7: Oui | E7: Hors TDR (**) | F7: - | G7: Actif / Diplome / Abandonne / Radie (extensible).
A8: P0_Parametres | B8: Genres | C8: Texte | D8: Non | E8: Initiative (*) | F8: - | G8: M / F.
A9: P0_Parametres | B9: Cat_Recettes | C9: Texte | D9: Oui | E9: Hors TDR (**) | F9: - | G9: Categories de recettes (liste separee, saisie EMSP).
A10: P0_Parametres | B10: Cat_Depenses | C10: Texte | D10: Oui | E10: Hors TDR (**) | F10: - | G10: Categories de depenses (liste separee, saisie EMSP).
A11: P0_Parametres | B11: Postes_budgetaires | C11: Texte | D11: Non | E11: Hors TDR (**) | F11: - | G11: Postes budgetaires saisis par l'EMSP.
A12: P0_Parametres | B12: Modes_paiement | C12: Texte | D12: Non | E12: Initiative (*) | F12: - | G12: Especes / Cheque / Virement / Autre.
A13: P0_Parametres | B13: Comptes_caisses | C13: Texte | D13: Oui | E13: Initiative (*) | F13: - | G13: Comptes et caisses (alimentent F2_Comptes).
... A164: F4_Bailleurs | B164: Saisi par | C164: Texte | D164: Non | E164: Initiative | F164: - | G164: Renseigne automatiquement (login).

Sheet Guide
A1: GUIDE D'UTILISATION — EMSP V1
A3: 1. AVANT DE COMMENCER
A4: Ordre de demarrage | B4: Renseigner d'abord l'onglet P0_Parametres : filieres, niveaux, sections, statuts, categories de recettes, categories de depenses, postes budgetaires, comptes/caisses, lieux de stage, annees. Toutes les listes deroulantes en dependent.
A5: Provenance des champs | B5: Sans marqueur = exige par le TDR ; (*) = initiative Webcreatys ; (**) = ajout hors TDR. Voir Legende et Dictionnaire.
A6: Filtres | B6: Chaque tableau a un filtre sur sa ligne d'en-tete (fleche en haut de colonne).
A7: Sauvegarde | B7: 100% hors-ligne. Copie datee chaque semaine sur cle USB dediee. Designer un referent sauvegarde.
A8: 2. ETUDIANTS
A9: Saisie / import | B9: Saisir dans A1_Etudiants, ou utiliser IMPORT_zone : coller le CSV national ; la colonne 'Statut vs base' indique NOUVEAU ou EXISTANT. Ne recopier dans A1 que les lignes NOUVEAU. Completer genre/origine si absents.
A10: Mise a jour hebdo | B10: Importer les nouveaux etudiants une fois par semaine.
A11: Presences | B11: A2_Presences : une ligne par etudiant / seance / creneau (10h, 12h, 15h, 17h). Pas d'absence partielle en V1.
A12: Documents | B12: A4_Documents_etud : cycle attestation (en attente conseil -> delai contestation 1 semaine -> imprimable).
A13: 3. ENSEIGNEMENTS & SALLES
A14: Sessions | B14: A3_Sessions relie matiere, enseignant et salle. L'occupation des salles se lit ici (pas de double saisie).
A15: Salles | B15: L1_Salles : type, capacite, equipements.
A16: Enseignants | B16: E1_Enseignants : fiche par enseignant. E2_Releve_heures : saisir le volume constate ; le total a payer se calcule seul (nb d'heures, sans montant).
A17: 4. STAGES
A18: Stages | B18: S1_Stages : referentiel des lieux + affectation (6 seances/an, 1 mois) + fiche de retour O/N. Les observations/plaintes sont distinctes de la presence.
A19: 5. FINANCES
A20: Mouvements | B20: F1_Mouvements : choisir d'abord le Sens (Recette ou Depense). La liste Categorie s'adapte automatiquement (listes separees). Saisir le montant dans la colonne Recette OU Depense (KMF). Indiquer le compte. Renseigner la Source de financement / Bailleur pour pouvoir sortir, par filtre, tout ce qui releve d'un bailleur donne.
A21: Comptes | B21: F2_Comptes : saisir le solde initial ; le solde courant se calcule automatiquement.
A23: 6. PILOTAGE
A24: Tableau de bord | B24: TDB_Direction : se met a jour automatiquement (effectifs, finances, heures, presence). Ne rien y saisir.
A25: Plan d'action | B25: G1_Plan_action : consigner les ecarts et actions correctives.
A26: Documents officiels | B26: H1_Biblio_docs : referencer textes OMS, reglementaires, protocoles (lien local hors-ligne).
A27: 7. REGLES IMPORTANTES
A28: Ne pas ecraser les formules | B28: Colonnes calculees (Total heures, Solde courant, Statut import, TDB) : ne jamais saisir a la main.
A29: Matricule = cle | B29: Le matricule relie tous les onglets : ne pas le modifier apres saisie.
A30: Depot du projet | B30: github.com/bWebreatys/emsp (branche main).

Sheet IMPORT_zone
A1: IMPORT CSV NATIONAL — coller le fichier, colonne H = statut vs base
A2: Matricule (*) | B2: Genre (*) | C2: Nom (*) | D2: Prenom (*) | E2: Date naissance (*) | F2: Lieu naissance (*) | G2: Niveau/Filiere (*) | H2: Statut vs base (*)
H3: =IF(A3="","",IF(COUNTIF(A1_Etudiants!$B$3:$B$50000,A3)=0,"NOUVEAU","EXISTANT"))
H4: =IF(A4="","",IF(COUNTIF(A1_Etudiants!$B$3:$B$50000,A4)=0,"NOUVEAU","EXISTANT"))
H5: =IF(A5="","",IF(COUNTIF(A1_Etudiants!$B$3:$B$50000,A5)=0,"NOUVEAU","EXISTANT"))
H6: =IF(A6="","",IF(COUNTIF(A1_Etudiants!$B$3:$B$50000,A6)=0,"NOUVEAU","EXISTANT"))
H7: =IF(A7="","",IF(COUNTIF(A1_Etudiants!$B$3:$B$50000,A7)=0,"NOUVEAU","EXISTANT"))
H8: =IF(A8="","",IF(COUNTIF(A1_Etudiants!$B$3:$B$50000,A8)=0,"NOUVEAU","EXISTANT"))
H9: =IF(A9="","",IF(COUNTIF(A1_Etudiants!$B$3:$B$50000,A9)=0,"NOUVEAU","EXISTANT"))
H10: =IF(A10="","",IF(COUNTIF(A1_Etudiants!$B$3:$B$50000,A10)=0,"NOUVEAU","EXISTANT"))
H11: =IF(A11="","",IF(COUNTIF(A1_Etudiants!$B$3:$B$50000,A11)=0,"NOUVEAU","EXISTANT"))
H12: =IF(A12="","",IF(COUNTIF(A1_Etudiants!$B$3:$B$50000,A12)=0,"NOUVEAU","EXISTANT"))
H13: =IF(A13="","",IF(COUNTIF(A1_Etudiants!$B$3:$B$50000,A13)=0,"NOUVEAU","EXISTANT"))
H14: =IF(A14="","",IF(COUNTIF(A1_Etudiants!$B$3:$B$50000,A14)=0,"NOUVEAU","EXISTANT"))
... H300: =IF(A300="","",IF(COUNTIF(A1_Etudiants!$B$3:$B$50000,A300)=0,"NOUVEAU","EXISTANT"))

Sheet D1_Modeles_docs
A1: MODELES DE DOCUMENTS — IMPRESSIONS & EDITIONS
A2: Cle doc | B2: Libelle | C2: En-tete | D2: Titre | E2: Corps | F2: Mentions / pied | G2: Libelle signataire | H2: Nb copies
A3: LISTE_ETUD | B3: Liste d'etudiants | C3: UNION DES COMORES Unite - Solidarite - Developpement Ministere de l'Education Nationale, de l'Enseignement Superieur et de la Recherche Universite des Comores Ecole de Medecine et de Sante Publique | D3: LISTE DES ETUDIANTS | G3: Le Chef de la Scolarite | H3: 1
A4: PRESENCE_VIERGE | B4: Feuille de presence vierge | C4: UNION DES COMORES Unite - Solidarite - Developpement Ministere de l'Education Nationale, de l'Enseignement Superieur et de la Recherche Universite des Comores Ecole de Medecine et de Sante Publique | D4: FICHE DE PRESENCE | E4: Hopital ou centre : ...................... Section : ...................... Periode du ...... / ...... / ...... au ...... / ...... / ...... | F4: En cas de rectification, les services concernes seront avertis. | G4: Signature du responsable de service | H4: 1
A5: RELEVE_IND | B5: Releve d'heures individuel (paie) | C5: UNION DES COMORES Unite - Solidarite - Developpement Ministere de l'Education Nationale, de l'Enseignement Superieur et de la Recherche Universite des Comores Ecole de Medecine et de Sante Publique | D5: RELEVE D'HEURES - ENSEIGNANT | E5: Enseignant : {nom} {prenom} (matricule {matricule}) Statut : {statut} Departement : {departement} Periode : {mois_annee} Volume horaire programme : {vol_prog} h Volume horaire constate : {vol_constate} h Total heures a payer : {total_heures} h Releve etabli pour la paie. Fait a Moroni, le {date_jour}. | F5: Heures uniquement (sans taux ni montant). | G5: L'enseignant / Le Chef de departement | H5: 1
A6: RELEVE_RECAP | B6: Recapitulatif mensuel des heures (tous enseignants) | C6: UNION DES COMORES Unite - Solidarite - Developpement Ministere de l'Education Nationale, de l'Enseignement Superieur et de la Recherche Universite des Comores Ecole de Medecine et de Sante Publique | D6: RECAPITULATIF MENSUEL DES HEURES - ENSEIGNANTS | F6: Heures uniquement (sans taux ni montant). | G6: La Direction | H6: 1
A7: RECU | B7: Recu de paiement | C7: UNION DES COMORES Unite - Solidarite - Developpement Ministere de l'Education Nationale, de l'Enseignement Superieur et de la Recherche Universite des Comores Ecole de Medecine et de Sante Publique | D7: RECU DE PAIEMENT | E7: Recu N {reference} Recu de {tiers} la somme de {montant} KMF (Francs comoriens), au titre de : {categorie} - {libelle}. Date de l'operation : {date_operation} Mode de paiement : {mode_paiement} Compte / caisse : {compte} Fait a Moroni, le {date_jour}. | F7: Ce recu fait foi de paiement. | G7: Le Comptable | H7: 2
A8: ATTESTATION | B8: Attestation de passage | C8: UNION DES COMORES Unite - Solidarite - Developpement Ministere de l'Education Nationale, de l'Enseignement Superieur et de la Recherche Universite des Comores Ecole de Medecine et de Sante Publique | D8: ATTESTATION DE PASSAGE | E8: Je soussigne(e), responsable de la scolarite de l'Ecole de Medecine et de Sante Publique, atteste que : {civilite} {prenom} {nom}, ne(e) le {date_naissance} a {lieu_naissance}, matricule {matricule}, est regulierement inscrit(e) en {niveau} - {filiere} (section {section}) au titre de l'annee academique {annee}. La presente attestation est delivree pour servir et valoir ce que de droit. Fait a Moroni, le {date_jour}. | G8: Le Chef de la Scolarite | H8: 1

Sheet L2_Reservations
A1: RESERVATIONS DE SALLES (HORS COURS)
A2: ID reservation (*) | B2: Salle (**) | C2: Date (**) | D2: Heure debut (**) | E2: Heure fin (**) | F2: Type (**) | G2: Reserve par (**) | H2: Motif / objet (**) | I2: Statut (**) | J2: Saisi par (*) | K2: Seance liee (ID session A3) | L2: Filiere | M2: Niveau | N2: Matiere | O2: Matricule ens. | P2: Enseignant

Sheet M1_Equipements
A1: EQUIPEMENTS — INVENTAIRE DE PILOTAGE
A2: ID equipement (*) | B2: Designation (**) | C2: Categorie (**) | D2: Salle / localisation (**) | E2: Date d'acquisition (**) | F2: Source de financement / Bailleur (**) | G2: Montant (KMF) (**) | H2: Reference / N piece (**) | I2: Etat (**) | J2: N inventaire / serie (**) | K2: Saisi par (*) | L2: Localisation provisoire (**) | M2: Quantite (**)
A3: EQ001 | B3: Ordinateur | C3: Informatique | D3: Bureau de la Direction | E3: 2015 | I3: Opérationnel | J3: UDC/EMSP/001- 001Bis /ORD/DG | K3: import inventaire | M3: 2
A4: EQ002 | B4: Imprimante | C4: Informatique | D4: Bureau de la Direction | E4: 2015 | I4: Opérationnel | J4: UDC/EMSP/001/IMP/DG | K4: import inventaire | M4: 1
A5: EQ003 | B5: Tableau de bureau | C5: Pédagogique | D5: Bureau de la Direction | E5: 2015 | I5: Opérationnel | J5: UD/EMSP/001/TAB/002/TAB/003/TAB/DG | K5: import inventaire | M5: 3
A6: EQ004 | B6: Etagere | C6: Mobilier | D6: Bureau de la Direction | E6: 20155 | I6: Opérationnel | J6: UDC/EMSP/001/ET/002/ET/DG | K6: import inventaire | M6: 2
A7: EQ005 | B7: Armoire | C7: Mobilier | D7: Bureau de la Direction | I7: Hors usage / En panne | J7: UDC/EMSP/008/A/DG | K7: import inventaire | M7: 1
A8: EQ006 | B8: Fauteuil | C8: Mobilier | D8: Bureau de la Direction | I8: Opérationnel | J8: UDC/EMSP/001/FOT/DG | K8: import inventaire | M8: 1
A9: EQ007 | B9: Chaise | C9: Mobilier | D9: Bureau de la Direction | I9: Opérationnel | J9: UDC/EMSP/001-002-003-004-005-006/CHA/DG | K9: import inventaire | M9: 6
A10: EQ008 | B10: Frigo | C10: Divers | D10: Bureau de la Direction | I10: Opérationnel | J10: UDC/EMSP/001/F/DG | K10: import inventaire | M10: 1
A11: EQ009 | B11: Rallonge | C11: Divers | D11: Bureau de la Direction | E11: 2018 | I11: Opérationnel | J11: UDC/EMSP/006/007/R/DG | K11: import inventaire | M11: 2
A12: EQ010 | B12: Climatiseur | C12: Climatisation | D12: Bureau de la Direction | E12: 2015 | I12: Opérationnel | J12: UDC/EMSP/001/CLI/DG | K12: import inventaire | M12: 1
A13: EQ011 | B13: Appareil telephoniques | C13: Divers | D13: Bureau de la Direction | E13: 2015 | I13: Opérationnel | J13: UDC/EMSP/001/AT/DG | K13: import inventaire | M13: 1
A14: EQ012 | B14: Coussin | C14: Mobilier | D14: Bureau de la Direction | I14: Moyen état | J14: UDC/EMSP/001/COU/DG | K14: import inventaire | M14: 1
A15: EQ013 | B15: Ordinateur | C15: Informatique | D15: Bureau de l'Assistant de direction | I15: Opérationnel | J15: UDC/EMSP/002/OR/AA | K15: import inventaire | M15: 1
A16: EQ014 | B16: Imprimante | C16: Informatique | D16: Bureau de l'Assistant de direction | E16: 2015 | I16: Opérationnel | J16: UDC/EMSP/002/IMP/AA | K16: import inventaire | M16: 1
A17: EQ015 | B17: Tableau de bureau | C17: Pédagogique | D17: Bureau de l'Assistant de direction | I17: Opérationnel | J17: UDC/EMSP/004-005/TAB/AA | K17: import inventaire | M17: 2
A18: EQ016 | B18: Etagere | C18: Mobilier | D18: Bureau de l'Assistant de direction | E18: 2015 | I18: Opérationnel | J18: UDC/EMSP/003/ET/AA | K18: import inventaire | M18: 1
A19: EQ017 | B19: Armoire | C19: Mobilier | D19: Bureau de l'Assistant de direction | I19: Moyen état | J19: UDC/EMSP/015/SO .UDC/AC/008/SG | K19: import inventaire | M19: 2
A20: EQ018 | B20: Fauteuil | C20: Mobilier | D20: Bureau de l'Assistant de direction | E20: 2015 | I20: Opérationnel | J20: UDC/EMSP/002/FOT/AA | K20: import inventaire | M20: 1
A21: EQ019 | B21: Chaise | C21: Mobilier | D21: Bureau de l'Assistant de direction | I21: Moyen état | J21: UDC/EMSP/007-008/AA.UDC/AC/01-090-014-0101/AC/SG | K21: import inventaire | M21: 6
A22: EQ020 | B22: Ondulair | C22: Informatique | D22: Bureau de l'Assistant de direction | E22: 2015 | I22: Hors usage / En panne | J22: UDC/EMSP/001-002/OND/AA | K22: import inventaire | M22: 2
A23: EQ021 | B23: Rallonge | C23: Divers | D23: Bureau de l'Assistant de direction | I23: Opérationnel | J23: UDC/EMSP/010-011/R/EMSP. UDC/EMSP/013/R/AA | K23: import inventaire | M23: 3
A24: EQ022 | B24: Switch | C24: Informatique | D24: Bureau de l'Assistant de direction | I24: Opérationnel | J24: UDC/EMSP/001/SW/EMSP | K24: import inventaire | M24: 1
A25: EQ023 | B25: Routeur | C25: Informatique | D25: Bureau de l'Assistant de direction | E25: 2018 | I25: Opérationnel | J25: UDC/EMSP/001/ROU/EMSP | K25: import inventaire | M25: 1
A26: EQ024 | B26: Ventilateur | C26: Climatisation | D26: Bureau de l'Assistant de direction | I26: Moyen état | J26: UDC/EMSP/001/VE/EMSP | K26: import inventaire | M26: 1
A27: EQ025 | B27: Fointaine d’eau | C27: Divers | D27: Bureau de l'Assistant de direction | E27: 2018 | I27: Opérationnel | J27: UDC/EMSP/001/FO/EMSP | K27: import inventaire | M27: 1
A28: EQ026 | B28: Ordinateur | C28: Informatique | D28: Bureau du Secrétariat | I28: Opérationnel | J28: UDC/EMSP/005/OR/S | K28: import inventaire | M28: 1
A29: EQ027 | B29: Imprimante | C29: Informatique | D29: Bureau du Secrétariat | K29: import inventaire | M29: 1
A30: EQ028 | B30: Table | C30: Mobilier | D30: Bureau du Secrétariat | I30: Opérationnel | J30: UDC/EMSP/008-009- 010/TAB/S | K30: import inventaire | M30: 3
A31: EQ029 | B31: Rallonge | C31: Divers | D31: Bureau du Secrétariat | E31: 2018 | I31: Opérationnel | J31: UDC/EMSP/014/R/S | K31: import inventaire | M31: 1
A32: EQ030 | B32: clim | C32: Climatisation | D32: Bureau du Secrétariat | I32: Hors usage / En panne | J32: UDC/EMSP/003/CLI/S | K32: import inventaire | M32: 1
A33: EQ031 | B33: Appareil telephonique | C33: Divers | D33: Bureau du Secrétariat | E33: 2018 | I33: Opérationnel | J33: UDC/EMSP/002/AT/S | K33: import inventaire | M33: 1
A34: EQ032 | B34: Ondulaire | C34: Informatique | D34: Bureau du Secrétariat | E34: 2015 | I34: Opérationnel | J34: UDC/EMSP/003/OND/S | K34: import inventaire | M34: 1
A35: EQ033 | B35: Armoire | C35: Mobilier | D35: Bureau du Secrétariat | I35: Moyen état | J35: UDC/EMSP/006/AR/S | K35: import inventaire | M35: 1
A36: EQ034 | B36: Bac à courrier | C36: Mobilier | D36: Bureau du Secrétariat | I36: Opérationnel | J36: UDC/EMSP/002/BAC/S | K36: import inventaire | M36: 1
A37: EQ035 | B37: Chaise | C37: Mobilier | D37: Bureau du Secrétariat | I37: Opérationnel | J37: UDC/EMSP/009-010-011/CHA/S et 283 | K37: import inventaire | M37: 4
A38: EQ036 | B38: Ordinateur | C38: Informatique | D38: Bureau du Gestionnaire | I38: Opérationnel | J38: UDC/EMSP/003-004/OR/GES | K38: import inventaire | M38: 2
A39: EQ037 | B39: Imprimante | C39: Informatique | D39: Bureau du Gestionnaire | E39: 2015 et 2018 | I39: Opérationnel | J39: UDC/EMSP/003-004/IMP/GES | K39: import inventaire | M39: 2
A40: EQ038 | B40: Table | C40: Mobilier | D40: Bureau du Gestionnaire | I40: Opérationnel | J40: UDC/EMSP/006-007-011-012/TAB/GES | K40: import inventaire | M40: 4
...

Sheet R1_Maquettes
A1: Référentiel des formations — Maquettes (UE / matières)
A2: Filière | B2: Niveau | C2: Semestre | D2: N° UE | E2: Intitulé UE / Module | F2: Matière / Contenu | G2: Enseignant | H2: CM | I2: TD | J2: TP | K2: Total heures | L2: Vol. horaire UE | M2: Crédit (ECTS) | N2: Coef
A3: Soins infirmiers | B3: L1 | C3: 1 | D3: 1 | E3: TIC (Technologie de l’information et de la communication) | F3: Communication | H3: 6 | I3: 4 | J3: 0 | K3: 10 | L3: 50 | M3: 3
A4: Soins infirmiers | B4: L1 | C4: 1 | D4: 1 | E4: TIC (Technologie de l’information et de la communication) | F4: Communication virtuelle | H4: 10 | I4: 0 | J4: 10 | K4: 20 | L4: 50 | M4: 3
A5: Soins infirmiers | B5: L1 | C5: 1 | D5: 1 | E5: TIC (Technologie de l’information et de la communication) | F5: Communication universitaire | H5: 15 | I5: 5 | J5: 0 | K5: 20 | L5: 50 | M5: 3
A6: Soins infirmiers | B6: L1 | C6: 1 | D6: 2 | E6: Anatomie et physiologie générale | F6: Introduction au corps humain | H6: 4 | I6: 2 | J6: 0 | K6: 6 | L6: 112 | M6: 7
A7: Soins infirmiers | B7: L1 | C7: 1 | D7: 2 | E7: Anatomie et physiologie générale | F7: Appareil respiratoire | H7: 6 | I7: 2 | J7: 0 | K7: 8 | L7: 112 | M7: 7
A8: Soins infirmiers | B8: L1 | C8: 1 | D8: 2 | E8: Anatomie et physiologie générale | F8: Le sang | H8: 6 | I8: 2 | J8: 0 | K8: 8 | L8: 112 | M8: 7
A9: Soins infirmiers | B9: L1 | C9: 1 | D9: 2 | E9: Anatomie et physiologie générale | F9: Système cardiovasculaire | H9: 6 | I9: 2 | J9: 0 | K9: 8 | L9: 112 | M9: 7
A10: Soins infirmiers | B10: L1 | C10: 1 | D10: 2 | E10: Anatomie et physiologie générale | F10: Liquides et électrolytes | H10: 8 | I10: 2 | J10: 0 | K10: 10 | L10: 112 | M10: 7
A11: Soins infirmiers | B11: L1 | C11: 1 | D11: 2 | E11: Anatomie et physiologie générale | F11: Système tégumentaire | H11: 6 | I11: 2 | J11: 0 | K11: 8 | L11: 112 | M11: 7
A12: Soins infirmiers | B12: L1 | C12: 1 | D12: 2 | E12: Anatomie et physiologie générale | F12: Appareil digestif | H12: 6 | I12: 2 | J12: 0 | K12: 8 | L12: 112 | M12: 7
A13: Soins infirmiers | B13: L1 | C13: 1 | D13: 2 | E13: Anatomie et physiologie générale | F13: Appareil urinaire | H13: 6 | I13: 2 | J13: 0 | K13: 8 | L13: 112 | M13: 7
A14: Soins infirmiers | B14: L1 | C14: 1 | D14: 2 | E14: Anatomie et physiologie générale | F14: Appareil genital masculin et feminin | H14: 6 | I14: 2 | J14: 0 | K14: 8 | L14: 112 | M14: 7
... A46: Soins infirmiers | B46: L1 | C46: 1 | D46: 9 | E46: Outils de recherche | F46: Méthodes statistiques | H46: 10 | I46: 8 | J46: 0 | K46: 18 | L46: 38 | M46: 2
A47: Soins infirmiers | B47: L1 | C47: 2 | D47: 10 | E47: Sciences humaines et sociales | F47: Sociologie | H47: 30 | I47: 4 | J47: 0 | K47: 34 | L47: 80 | M47: 5 | N47: Coef
A48: Soins infirmiers | B48: L1 | C48: 2 | D48: 10 | E48: Sciences humaines et sociales | F48: Psychologie | H48: 30 | I48: 4 | J48: 0 | K48: 34 | L48: 80 | M48: 5 | N48: Coef
A49: Soins infirmiers | B49: L1 | C49: 2 | D49: 10 | E49: Sciences humaines et sociales | F49: Anthropologie et ethnologie | H49: 10 | I49: 2 | J49: 0 | K49: 12 | L49: 80 | M49: 5 | N49: Coef
A50: Soins infirmiers | B50: L1 | C50: 2 | D50: 12 | E50: Aspects professionnels éthiques et juridiques de la profession d’infirmière /1 | F50: Les métiers d’infirmier et de sage-femme | H50: 6 | I50: 2 | J50: 0 | K50: 8 | L50: 46 | M50: 3 | N50: Coef
A51: Soins infirmiers | B51: L1 | C51: 2 | D51: 12 | E51: Aspects professionnels éthiques et juridiques de la profession d’infirmière /1 | F51: Législation et réglementation de la profession et protection du public | H51: 8 | I51: 2 | J51: 0 | K51: 10 | L51: 46 | M51: 3 | N51: Coef
A52: Soins infirmiers | B52: L1 | C52: 2 | D52: 12 | E52: Aspects professionnels éthiques et juridiques de la profession d’infirmière /1 | F52: Déontologie, théories et principes éthiques | H52: 16 | I52: 4 | J52: 0 | K52: 20 | L52: 46 | M52: 3 | N52: Coef
A53: Soins infirmiers | B53: L1 | C53: 2 | D53: 12 | E53: Aspects professionnels éthiques et juridiques de la profession d’infirmière /1 | F53: Organisations et associations professionnelles | H53: 6 | I53: 2 | J53: 0 | K53: 8 | L53: 46 | M53: 3 | N53: Coef
A54: Soins infirmiers | B54: L1 | C54: 2 | D54: 13 | E54: Nutrition et diététique/1 | F54: Alimentation et nutrition : les aliments organiques et leurs fonctions | H54: 24 | I54: 6 | J54: 0 | K54: 30 | L54: 30 | M54: 2 | N54: Coef
A55: Soins infirmiers | B55: L1 | C55: 2 | D55: 13 | E55: Nutrition et diététique/1 | F55: Métabolisme | L55: 30 | M55: 2 | N55: Coef
A56: Soins infirmiers | B56: L1 | C56: 2 | D56: 13 | E56: Nutrition et diététique/1 | F56: Besoins nutritionnels des différentes tranches d’âge | L56: 30 | M56: 2 | N56: Coef
A57: Soins infirmiers | B57: L1 | C57: 2 | D57: 13 | E57: Nutrition et diététique/1 | F57: Sécurité et disponibilité alimentaire | L57: 30 | M57: 2 | N57: Coef
A58: Soins infirmiers | B58: L1 | C58: 2 | D58: 13 | E58: Nutrition et diététique/1 | F58: Aspects comportementaux et culturels de la nutrition | L58: 30 | M58: 2 | N58: Coef
A59: Soins infirmiers | B59: L1 | C59: 2 | D59: 14 | E59: Prise en charge des affections primaires | F59: Maladies infectieuses | H59: 14 | I59: 6 | J59: 0 | K59: 20 | L59: 150 | M59: 10 | N59: Coef
A60: Soins infirmiers | B60: L1 | C60: 2 | D60: 14 | E60: Prise en charge des affections primaires | F60: Soins infirmiers en maladies infectieuses | H60: 10 | I60: 2 | J60: 6 | K60: 18 | L60: 150 | M60: 10 | N60: Coef
A61: Soins infirmiers | B61: L1 | C61: 2 | D61: 14 | E61: Prise en charge des affections primaires | F61: Affections respiratoires | H61: 10 | I61: 4 | J61: 8 | K61: 22 | L61: 150 | M61: 10 | N61: Coef
A62: Soins infirmiers | B62: L1 | C62: 2 | D62: 14 | E62: Prise en charge des affections primaires | F62: Soins infirmiers en affections respiratoires | H62: 10 | I62: 4 | J62: 6 | K62: 20 | L62: 150 | M62: 10 | N62: Coef
A63: Soins infirmiers | B63: L1 | C63: 2 | D63: 14 | E63: Prise en charge des affections primaires | F63: Pathologies digestives | H63: 22 | I63: 6 | J63: 0 | K63: 28 | L63: 150 | M63: 10 | N63: Coef
A64: Soins infirmiers | B64: L1 | C64: 2 | D64: 14 | E64: Prise en charge des affections primaires | F64: Soins infirmiers en affections digestives | H64: 10 | I64: 4 | J64: 6 | K64: 20 | L64: 150 | M64: 10 | N64: Coef
A65: Soins infirmiers | B65: L1 | C65: 2 | D65: 14 | E65: Prise en charge des affections primaires | F65: Pharmacologie et thérapeutique | H65: 16 | I65: 6 | J65: 0 | K65: 22 | L65: 150 | M65: 10 | N65: Coef
A66: Soins infirmiers | B66: L2 | C66: 3 | D66: 16 | E66: Obstétrique normale | F66: Physiologie de la grossesse | H66: 10 | I66: 2 | J66: 0 | K66: 12 | L66: 36 | M66: 2 | N66: Coef
A67: Soins infirmiers | B67: L2 | C67: 3 | D67: 16 | E67: Obstétrique normale | F67: Signe, diagnostique et surveillance de la grossesse | H67: 6 | I67: 2 | J67: 0 | K67: 8 | L67: 36 | M67: 2 | N67: Coef
A68: Soins infirmiers | B68: L2 | C68: 3 | D68: 16 | E68: Obstétrique normale | F68: Accouchement eutocique | H68: 8 | I68: 2 | J68: 6 | K68: 16 | L68: 36 | M68: 2 | N68: Coef
A69: Soins infirmiers | B69: L2 | C69: 3 | D69: 18 | E69: Education à la santé et communication | F69: Education à la santé | H69: 4 | I69: 2 | J69: 0 | K69: 6 | L69: 24 | M69: 1 | N69: Coef
A70: Soins infirmiers | B70: L2 | C70: 3 | D70: 18 | E70: Education à la santé et communication | F70: Education thérapeutique du patient | H70: 4 | I70: 4 | J70: 0 | K70: 8 | L70: 24 | M70: 1 | N70: Coef
... A80: Soins infirmiers | B80: L2 | C80: 3 | D80: 21 | E80: Soins promotionnels, préventifs et adaptatifs/1 | F80: Santé de la reproduction | H80: 20 | I80: 2 | J80: 0 | K80: 22 | L80: 64 | M80: 4 | N80: Coef
...

Sheet S2_Lieux_stage
A1: LIEUX DE STAGE — REFERENTIEL ET QUOTAS
A2: Lieu / structure (*) | B2: Service (*) | C2: Commune (*) | D2: Niveau concerne (*) | E2: Quota (*) | F2: Periode de disponibilite (*)

Sheet L3_Besoins
A1: EXPRESSION DE BESOIN (LOGISTIQUE)
A2: ID besoin (*) | B2: Date d'expression (**) | C2: Type de besoin (**) | D2: Equipement concerne (**) | E2: Libelle du besoin (**) | F2: Quantite (**) | G2: Localisation / salle (**) | H2: Priorite (**) | I2: Statut (**) | J2: Cout estime (KMF) (**) | K2: Demandeur (**) | L2: Observations (**) | M2: Saisi par (*)

Sheet J1_Journal_eleves
A1: JOURNAL PERMANENT DES ELEVES (clotures successives)
A2: Matricule | B2: Nom | C2: Prenom | D2: Filiere | E2: Niveau atteint (*) | F2: Periode (entree - sortie) (*) | G2: Statut final (*) | H2: Diplome obtenu (*) | I2: Mention (*) | J2: Ref. archive (*) | K2: Cloture le (*) | L2: Cloture par (*)

Sheet J2_Journal_compta
A1: JOURNAL PERMANENT DE LA COMPTABILITE (exercices clos)
A2: Annee (*) | B2: Total recettes (KMF) (*) | C2: Total depenses (KMF) (*) | D2: Solde de cloture (KMF) (*) | E2: Ref. archive (*) | F2: Cloture le (*) | G2: Cloture par (*)

Sheet E3_Seances_faites
A1: SUIVI DES SEANCES REALISEES (exceptions : remplacant / cours annule / duree)
